Workbook

Sheet Summary
A1: Paladin (ScalpX) — trading information extracted from posted images
A2: Channel #🔮｜paladin, 2026-05-06 to 2026-08-21. Every one of the 320 images (incl. 2 screen recordings) was viewed and transcribed; numbers are copied from the image, never inferred.
A4: Coverage
A5: Images analysed | B5: =COUNTA(Images!A2:A100000) -> 320
A6: Images with trading information | B6: =COUNTIF(Images!D2:D100000,"yes") -> 318
A7: Images with no trading information | B7: =COUNTIF(Images!D2:D100000,"no") -> 2
A8: Trade rows extracted | B8: =COUNTA(Trades!C2:C100000) -> 335
A9: Price charts captured | B9: =COUNTA(Charts!A2:A100000) -> 24
A10: Rows flagged medium confidence | B10: =COUNTIF(Images!Q2:Q100000,"medium") -> 38
A12: Field fill rate (of trade rows)
A13: Entry price | B13: =COUNT(Trades!H2:H100000) -> 224 | C13: =IF($B$8=0,"-",B13/$B$8) -> 0.66865672
A14: Exit / close price | B14: =COUNT(Trades!I2:I100000) -> 223 | C14: =IF($B$8=0,"-",B14/$B$8) -> 0.66567164
A15: ROI % | B15: =COUNT(Trades!K2:K100000) -> 268 | C15: =IF($B$8=0,"-",B15/$B$8) -> 0.8
A16: Leverage | B16: =COUNT(Trades!F2:F100000) -> 234 | C16: =IF($B$8=0,"-",B16/$B$8) -> 0.69850746
A17: Side (long/short) | B17: =COUNTIF(Trades!E2:E100000,"long")+COUNTIF(Trades!E2:E100000,"short") -> 307 | C17: =IF($B$8=0,"-",B17/$B$8) -> 0.91641791
A18: Stop loss | B18: =COUNT(Trades!O2:O100000) -> 4 | C18: =IF($B$8=0,"-",B18/$B$8) -> 0.011940299
A19: Take profit | B19: =COUNTA(Trades!P2:P100000) -> 3 | C19: =IF($B$8=0,"-",B19/$B$8) -> 0.0089552239
A20: Liquidation price | B20: =COUNT(Trades!Q2:Q100000) -> 3 | C20: =IF($B$8=0,"-",B20/$B$8) -> 0.0089552239
A21: PnL in USD | B21: =COUNT(Trades!L2:L100000) -> 10 | C21: =IF($B$8=0,"-",B21/$B$8) -> 0.029850746
A22: Stop losses and take profits are almost never in the images — he writes them in the message text instead (323 messages mention an SL, 280 mention a TP/target).
A24: Most traded symbols (by trade rows)
A25: Symbol | B25: Rows | C25: Long | D25: Short | E25: Avg ROI % shown
A26: BTC | B26: =COUNTIF(Trades!$D$2:$D$100000,$A26) -> 144 | C26: =COUNTIFS(Trades!$D$2:$D$100000,$A26,Trades!$E$2:$E$100000,"long") -> 113 | D26: =COUNTIFS(Trades!$D$2:$D$100000,$A26,Trades!$E$2:$E$100000,"short") -> 15 | E26: =IFERROR(AVERAGEIF(Trades!$D$2:$D$100000,$A26,Trades!$K$2:$K$100000),"-") -> 219.20604
A27: ETH | B27: =COUNTIF(Trades!$D$2:$D$100000,$A27) -> 18 | C27: =COUNTIFS(Trades!$D$2:$D$100000,$A27,Trades!$E$2:$E$100000,"long") -> 10 | D27: =COUNTIFS(Trades!$D$2:$D$100000,$A27,Trades!$E$2:$E$100000,"short") -> 5 | E27: =IFERROR(AVERAGEIF(Trades!$D$2:$D$100000,$A27,Trades!$K$2:$K$100000),"-") -> 173.065
A28: SOL | B28: =COUNTIF(Trades!$D$2:$D$100000,$A28) -> 16 | C28: =COUNTIFS(Trades!$D$2:$D$100000,$A28,Trades!$E$2:$E$100000,"long") -> 14 | D28: =COUNTIFS(Trades!$D$2:$D$100000,$A28,Trades!$E$2:$E$100000,"short") -> 1 | E28: =IFERROR(AVERAGEIF(Trades!$D$2:$D$100000,$A28,Trades!$K$2:$K$100000),"-") -> 216.87667
A29: SUI | B29: =COUNTIF(Trades!$D$2:$D$100000,$A29) -> 16 | C29: =COUNTIFS(Trades!$D$2:$D$100000,$A29,Trades!$E$2:$E$100000,"long") -> 15 | D29: =COUNTIFS(Trades!$D$2:$D$100000,$A29,Trades!$E$2:$E$100000,"short") -> 0 | E29: =IFERROR(AVERAGEIF(Trades!$D$2:$D$100000,$A29,Trades!$K$2:$K$100000),"-") -> 580.80308
A30: HYPE | B30: =COUNTIF(Trades!$D$2:$D$100000,$A30) -> 14 | C30: =COUNTIFS(Trades!$D$2:$D$100000,$A30,Trades!$E$2:$E$100000,"long") -> 11 | D30: =COUNTIFS(Trades!$D$2:$D$100000,$A30,Trades!$E$2:$E$100000,"short") -> 2 | E30: =IFERROR(AVERAGEIF(Trades!$D$2:$D$100000,$A30,Trades!$K$2:$K$100000),"-") -> 197.3225
A31: ZEC | B31: =COUNTIF(Trades!$D$2:$D$100000,$A31) -> 14 | C31: =COUNTIFS(Trades!$D$2:$D$100000,$A31,Trades!$E$2:$E$100000,"long") -> 10 | D31: =COUNTIFS(Trades!$D$2:$D$100000,$A31,Trades!$E$2:$E$100000,"short") -> 4 | E31: =IFERROR(AVERAGEIF(Trades!$D$2:$D$100000,$A31,Trades!$K$2:$K$100000),"-") -> 202.76308
A32: XRP | B32: =COUNTIF(Trades!$D$2:$D$100000,$A32) -> 8 | C32: =COUNTIFS(Trades!$D$2:$D$100000,$A32,Trades!$E$2:$E$100000,"long") -> 7 | D32: =COUNTIFS(Trades!$D$2:$D$100000,$A32,Trades!$E$2:$E$100000,"short") -> 0 | E32: =IFERROR(AVERAGEIF(Trades!$D$2:$D$100000,$A32,Trades!$K$2:$K$100000),"-") -> 148.2
A33: WLD | B33: =COUNTIF(Trades!$D$2:$D$100000,$A33) -> 7 | C33: =COUNTIFS(Trades!$D$2:$D$100000,$A33,Trades!$E$2:$E$100000,"long") -> 6 | D33: =COUNTIFS(Trades!$D$2:$D$100000,$A33,Trades!$E$2:$E$100000,"short") -> 1 | E33: =IFERROR(AVERAGEIF(Trades!$D$2:$D$100000,$A33,Trades!$K$2:$K$100000),"-") -> 353.64167
A34: STABLE | B34: =COUNTIF(Trades!$D$2:$D$100000,$A34) -> 5 | C34: =COUNTIFS(Trades!$D$2:$D$100000,$A34,Trades!$E$2:$E$100000,"long") -> 5 | D34: =COUNTIFS(Trades!$D$2:$D$100000,$A34,Trades!$E$2:$E$100000,"short") -> 0 | E34: =IFERROR(AVERAGEIF(Trades!$D$2:$D$100000,$A34,Trades!$K$2:$K$100000),"-") -> 206.1
A35: FIL | B35: =COUNTIF(Trades!$D$2:$D$100000,$A35) -> 5 | C35: =COUNTIFS(Trades!$D$2:$D$100000,$A35,Trades!$E$2:$E$100000,"long") -> 5 | D35: =COUNTIFS(Trades!$D$2:$D$100000,$A35,Trades!$E$2:$E$100000,"short") -> 0 | E35: =IFERROR(AVERAGEIF(Trades!$D$2:$D$100000,$A35,Trades!$K$2:$K$100000),"-") -> 100.52
A36: TAO | B36: =COUNTIF(Trades!$D$2:$D$100000,$A36) -> 5 | C36: =COUNTIFS(Trades!$D$2:$D$100000,$A36,Trades!$E$2:$E$100000,"long") -> 5 | D36: =COUNTIFS(Trades!$D$2:$D$100000,$A36,Trades!$E$2:$E$100000,"short") -> 0 | E36: =IFERROR(AVERAGEIF(Trades!$D$2:$D$100000,$A36,Trades!$K$2:$K$100000),"-") -> 157.892
A37: BNB | B37: =COUNTIF(Trades!$D$2:$D$100000,$A37) -> 5 | C37: =COUNTIFS(Trades!$D$2:$D$100000,$A37,Trades!$E$2:$E$100000,"long") -> 5 | D37: =COUNTIFS(Trades!$D$2:$D$100000,$A37,Trades!$E$2:$E$100000,"short") -> 0 | E37: =IFERROR(AVERAGEIF(Trades!$D$2:$D$100000,$A37,Trades!$K$2:$K$100000),"-") -> 176.565
... A40: BEAT | B40: =COUNTIF(Trades!$D$2:$D$100000,$A40) -> 4 | C40: =COUNTIFS(Trades!$D$2:$D$100000,$A40,Trades!$E$2:$E$100000,"long") -> 0 | D40: =COUNTIFS(Trades!$D$2:$D$100000,$A40,Trades!$E$2:$E$100000,"short") -> 4 | E40: =IFERROR(AVERAGEIF(Trades!$D$2:$D$100000,$A40,Trades!$K$2:$K$100000),"-") -> 530.98333
A42: Leverage used (where the image shows it)
A43: Leverage | B43: Trade rows
A44: 3 | B44: =COUNTIF(Trades!$F$2:$F$100000,$A44) -> 4
A45: 10 | B45: =COUNTIF(Trades!$F$2:$F$100000,$A45) -> 7
A46: 20 | B46: =COUNTIF(Trades!$F$2:$F$100000,$A46) -> 14
...

Sheet Trades
A1: Date | B1: Time | C1: Symbol | D1: Base | E1: Side | F1: Leverage | G1: Margin mode | H1: Entry price | I1: Exit price | J1: Exit price type | K1: ROI % | L1: PnL USD | M1: Position size | N1: Margin USD | O1: Stop loss | P1: Take profits | Q1: Liq. price | R1: Status | S1: Platform | T1: Image type | U1: Trade notes | V1: Message posted with image | W1: Image file | X1: Confidence | Y1: Discord link
A2: 2026-05-06 | B2: 23:47:41 | C2: ASTERUSDT | D2: ASTER | R2: closed | S2: Discord | T2: discord_message_screenshot | U2: Listed as a winning trade in the recap (symbol written as base ticker only). | V2: I have been trading for the past month in journals and here's my progress so far **25** trades **22** Wins **3** BE **0** loss Can track it all in the journal -> https://discord.com/channels/1042855255089623100/1496387902140321885/1501536396127633418 @Paladin Notify | W2: 001_2026-05-06_234741_Screenshot_20260507-014653.png | X2: high | Y2: https://discord.com/channels/1042855255089623100/1501271173588193290/1501686917828448277
A3: 2026-05-06 | B3: 23:47:41 | C3: AXSUSDT | D3: AXS | R3: closed | S3: Discord | T3: discord_message_screenshot | U3: Listed as a winning trade in the recap. | V3: I have been trading for the past month in journals and here's my progress so far **25** trades **22** Wins **3** BE **0** loss Can track it all in the journal -> https://discord.com/channels/1042855255089623100/1496387902140321885/1501536396127633418 @Paladin Notify | W3: 001_2026-05-06_234741_Screenshot_20260507-014653.png | X3: high | Y3: https://discord.com/channels/1042855255089623100/1501271173588193290/1501686917828448277
A4: 2026-05-06 | B4: 23:47:41 | C4: IRYSUSDT | D4: IRYS | R4: closed | S4: Discord | T4: discord_message_screenshot | U4: Listed as a winning trade in the recap. | V4: I have been trading for the past month in journals and here's my progress so far **25** trades **22** Wins **3** BE **0** loss Can track it all in the journal -> https://discord.com/channels/1042855255089623100/1496387902140321885/1501536396127633418 @Paladin Notify | W4: 001_2026-05-06_234741_Screenshot_20260507-014653.png | X4: high | Y4: https://discord.com/channels/1042855255089623100/1501271173588193290/1501686917828448277
A5: 2026-05-06 | B5: 23:47:41 | C5: BTCUSDT | D5: BTC | R5: closed | S5: Discord | T5: discord_message_screenshot | U5: Listed as a winning trade in the recap (BTC win 1 of 13 listed). | V5: I have been trading for the past month in journals and here's my progress so far **25** trades **22** Wins **3** BE **0** loss Can track it all in the journal -> https://discord.com/channels/1042855255089623100/1496387902140321885/1501536396127633418 @Paladin Notify | W5: 001_2026-05-06_234741_Screenshot_20260507-014653.png | X5: high | Y5: https://discord.com/channels/1042855255089623100/1501271173588193290/1501686917828448277
A6: 2026-05-06 | B6: 23:47:41 | C6: BTCUSDT | D6: BTC | R6: closed | S6: Discord | T6: discord_message_screenshot | U6: Listed as a winning trade in the recap (BTC win 2 of 13 listed). | V6: I have been trading for the past month in journals and here's my progress so far **25** trades **22** Wins **3** BE **0** loss Can track it all in the journal -> https://discord.com/channels/1042855255089623100/1496387902140321885/1501536396127633418 @Paladin Notify | W6: 001_2026-05-06_234741_Screenshot_20260507-014653.png | X6: high | Y6: https://discord.com/channels/1042855255089623100/1501271173588193290/1501686917828448277
A7: 2026-05-06 | B7: 23:47:41 | C7: BTCUSDT | D7: BTC | R7: closed | S7: Discord | T7: discord_message_screenshot | U7: Listed as a winning trade in the recap (BTC win 3 of 13 listed). | V7: I have been trading for the past month in journals and here's my progress so far **25** trades **22** Wins **3** BE **0** loss Can track it all in the journal -> https://discord.com/channels/1042855255089623100/1496387902140321885/1501536396127633418 @Paladin Notify | W7: 001_2026-05-06_234741_Screenshot_20260507-014653.png | X7: high | Y7: https://discord.com/channels/1042855255089623100/1501271173588193290/1501686917828448277
A8: 2026-05-06 | B8: 23:47:41 | C8: ETHUSDT | D8: ETH | R8: closed | S8: Discord | T8: discord_message_screenshot | U8: Listed as a winning trade in the recap (ETH win 1 of 3 listed). | V8: I have been trading for the past month in journals and here's my progress so far **25** trades **22** Wins **3** BE **0** loss Can track it all in the journal -> https://discord.com/channels/1042855255089623100/1496387902140321885/1501536396127633418 @Paladin Notify | W8: 001_2026-05-06_234741_Screenshot_20260507-014653.png | X8: high | Y8: https://discord.com/channels/1042855255089623100/1501271173588193290/1501686917828448277
A9: 2026-05-06 | B9: 23:47:41 | C9: HYPEUSDT | D9: HYPE | R9: closed | S9: Discord | T9: discord_message_screenshot | U9: Listed as a winning trade in the recap. | V9: I have been trading for the past month in journals and here's my progress so far **25** trades **22** Wins **3** BE **0** loss Can track it all in the journal -> https://discord.com/channels/1042855255089623100/1496387902140321885/1501536396127633418 @Paladin Notify | W9: 001_2026-05-06_234741_Screenshot_20260507-014653.png | X9: high | Y9: https://discord.com/channels/1042855255089623100/1501271173588193290/1501686917828448277
A10: 2026-05-06 | B10: 23:47:41 | C10: PEPEUSDT | D10: PEPE | R10: closed | S10: Discord | T10: discord_message_screenshot | U10: Listed as a winning trade in the recap. | V10: I have been trading for the past month in journals and here's my progress so far **25** trades **22** Wins **3** BE **0** loss Can track it all in the journal -> https://discord.com/channels/1042855255089623100/1496387902140321885/1501536396127633418 @Paladin Notify | W10: 001_2026-05-06_234741_Screenshot_20260507-014653.png | X10: high | Y10: https://discord.com/channels/1042855255089623100/1501271173588193290/1501686917828448277
A11: 2026-05-06 | B11: 23:47:41 | C11: ETHUSDT | D11: ETH | R11: closed | S11: Discord | T11: discord_message_screenshot | U11: Listed as a winning trade in the recap (ETH win 2 of 3 listed). | V11: I have been trading for the past month in journals and here's my progress so far **25** trades **22** Wins **3** BE **0** loss Can track it all in the journal -> https://discord.com/channels/1042855255089623100/1496387902140321885/1501536396127633418 @Paladin Notify | W11: 001_2026-05-06_234741_Screenshot_20260507-014653.png | X11: high | Y11: https://discord.com/channels/1042855255089623100/1501271173588193290/1501686917828448277
A12: 2026-05-06 | B12: 23:47:41 | C12: BTCUSDT | D12: BTC | R12: closed | S12: Discord | T12: discord_message_screenshot | U12: Listed as a winning trade in the recap (BTC win 4 of 13 listed). | V12: I have been trading for the past month in journals and here's my progress so far **25** trades **22** Wins **3** BE **0** loss Can track it all in the journal -> https://discord.com/channels/1042855255089623100/1496387902140321885/1501536396127633418 @Paladin Notify | W12: 001_2026-05-06_234741_Screenshot_20260507-014653.png | X12: high | Y12: https://discord.com/channels/1042855255089623100/1501271173588193290/1501686917828448277
A13: 2026-05-06 | B13: 23:47:41 | C13: BTCUSDT | D13: BTC | R13: closed | S13: Discord | T13: discord_message_screenshot | U13: Listed as a winning trade in the recap (BTC win 5 of 13 listed). | V13: I have been trading for the past month in journals and here's my progress so far **25** trades **22** Wins **3** BE **0** loss Can track it all in the journal -> https://discord.com/channels/1042855255089623100/1496387902140321885/1501536396127633418 @Paladin Notify | W13: 001_2026-05-06_234741_Screenshot_20260507-014653.png | X13: high | Y13: https://discord.com/channels/1042855255089623100/1501271173588193290/1501686917828448277
... A25: 2026-05-06 | B25: 23:47:41 | C25: BTCUSDT | D25: BTC | R25: closed | S25: Discord | T25: discord_message_screenshot | U25: Listed as a break-even (BE) trade in the recap. | V25: I have been trading for the past month in journals and here's my progress so far **25** trades **22** Wins **3** BE **0** loss Can track it all in the journal -> https://discord.com/channels/1042855255089623100/1496387902140321885/1501536396127633418 @Paladin Notify | W25: 001_2026-05-06_234741_Screenshot_20260507-014653.png | X25: high | Y25: https://discord.com/channels/1042855255089623100/1501271173588193290/1501686917828448277
A26: 2026-05-08 | B26: 13:48:41 | C26: BTCUSDT | D26: BTC | E26: long | H26: 79564.8 | R26: open | S26: unknown | T26: open_positions_screenshot | U26: Only the field 'Entry Price (USDT) 79,564.80' is visible. Symbol and side are NOT shown in the image: BTC is taken from the accompanying message context and 'long' from the message suggesting taking 20% profit at 80.5k above this entry. Note this entry (79,564.80) differs from the 79,764.40 entry shown on the later BTCUSDT Long 100X Bybit share cards (images 014/017). | V26: BTC started moving, you can take 20% @ 80.5k if you want, I'll update whenever I close! | W26: 002_2026-05-08_134841_Screenshot_20260508-1547142.png | X26: medium | Y26: https://discord.com/channels/1042855255089623100/1501271173588193290/1502260952098279615
A27: 2026-05-08 | B27: 18:44:20 | C27: UNIUSDT | D27: UNI | E27: long | F27: 50 | K27: 101.21 | R27: closed | S27: Bybit | T27: pnl_share_card | U27: Cropped share card: only header and ROI visible. Same card appears in full as image 015 (Entry 3.458 / Exit 3.528). Per message this was a 50% partial close (~0.7R); remaining half held with SL moved to BE 3.46, his own TP 3.7, followers could hold to 4 (those levels are from the message, not the image). | V27: Okay let's treat as our first win Closing 50% UNI for 0.7 R move, I'll take personally fully TP @ 3.7 You can hold till 4 SL @ BE 3.46 @Paladin Notify | W27: 003_2026-05-08_184420_Screenshot_20260508-203512.png | X27: medium | Y27: https://discord.com/channels/1042855255089623100/1501271173588193290/1502335355628687451
A28: 2026-05-09 | B28: 04:45:42 | C28: KERNELUSDT | D28: KERNEL | E28: long | F28: 20 | H28: 0.06454 | I28: 0.06615 | J28: mark | K28: 49.35 | R28: open | S28: Bybit | T28: pnl_share_card | U28: Card label reads 'Current Price' (position still open). Per message this is TP1 with the next TP at 0.0673 (not shown on the card). | V28: KERNEL TP1 here, next TP @ 0.0673 @Paladin Notify | W28: 009_2026-05-09_044542_Screenshot_20260509-064308.png | X28: high | Y28: https://discord.com/channels/1042855255089623100/1501271173588193290/1502486692232298586
A29: 2026-05-09 | B29: 04:48:32 | C29: KERNELUSDT | D29: KERNEL | E29: long | F29: 20 | H29: 0.06454 | I29: 0.06615 | J29: mark | K29: 49.35 | R29: open | S29: Bybit | T29: pnl_share_card | U29: Card label reads 'Current Price' (position still open). Identical screenshot to image 009 (same file name Screenshot_20260509-064308), re-posted in the batch of running trades. | V29: All trades running in good profits, take TP whenever you want, don't let them round trip. I'll update when I close. | W29: 010_2026-05-09_044832_Screenshot_20260509-064308.png | X29: high | Y29: https://discord.com/channels/1042855255089623100/1501271173588193290/1502487407654862971
A30: 2026-05-09 | B30: 04:48:32 | C30: AVNTUSDT | D30: AVNT | E30: long | F30: 50 | H30: 0.15851 | I30: 0.16787 | J30: mark | K30: 265.55 | R30: open | S30: Bybit | T30: pnl_share_card | U30: Card label reads 'Current Price' (position still open). | V30: All trades running in good profits, take TP whenever you want, don't let them round trip. I'll update when I close. | W30: 011_2026-05-09_044832_Screenshot_20260509-064552.png | X30: high | Y30: https://discord.com/channels/1042855255089623100/1501271173588193290/1502487407654862971
A31: 2026-05-09 | B31: 04:48:32 | C31: SNXUSDT | D31: SNX | E31: long | F31: 25 | H31: 0.3545 | I31: 0.3727 | J31: mark | K31: 118.67 | R31: open | S31: Bybit | T31: pnl_share_card | U31: Card label reads 'Current Price' (position still open). | V31: All trades running in good profits, take TP whenever you want, don't let them round trip. I'll update when I close. | W31: 012_2026-05-09_044832_Screenshot_20260509-064638.png | X31: high | Y31: https://discord.com/channels/1042855255089623100/1501271173588193290/1502487407654862971
A32: 2026-05-09 | B32: 04:48:32 | C32: ZROUSDT | D32: ZRO | E32: long | F32: 50 | H32: 1.4744 | I32: 1.4849 | J32: mark | K32: 34.43 | R32: open | S32: Bybit | T32: pnl_share_card | U32: Card label reads 'Current Price' (position still open). | V32: All trades running in good profits, take TP whenever you want, don't let them round trip. I'll update when I close. | W32: 013_2026-05-09_044832_Screenshot_20260509-064657.png | X32: high | Y32: https://discord.com/channels/1042855255089623100/1501271173588193290/1502487407654862971
A33: 2026-05-09 | B33: 04:48:32 | C33: BTCUSDT | D33: BTC | E33: long | F33: 100 | H33: 79764.4 | I33: 80333.9 | J33: mark | K33: 67.25 | R33: open | S33: Bybit | T33: pnl_share_card | U33: Card label reads 'Current Price' (position still open). Same position later closed at 80,341.20 (image 017). | V33: All trades running in good profits, take TP whenever you want, don't let them round trip. I'll update when I close. | W33: 014_2026-05-09_044832_Screenshot_20260509-064717.png | X33: high | Y33: https://discord.com/channels/1042855255089623100/1501271173588193290/1502487407654862971
A34: 2026-05-09 | B34: 04:48:32 | C34: UNIUSDT | D34: UNI | E34: long | F34: 50 | H34: 3.458 | I34: 3.528 | J34: close | K34: 101.21 | R34: closed | S34: Bybit | T34: pnl_share_card | U34: Card label reads 'Exit Price' (closed). Full version of the cropped card in image 003; this is the 50% partial close at ~0.7R announced on May 8 (the remainder was exited at 3.7 per his later message). | V34: All trades running in good profits, take TP whenever you want, don't let them round trip. I'll update when I close. | W34: 015_2026-05-09_044832_Screenshot_20260509-063448.png | X34: high | Y34: https://discord.com/channels/1042855255089623100/1501271173588193290/1502487407654862971
A35: 2026-05-09 | B35: 04:52:10 | C35: SYRUPUSDT | D35: SYRUP | E35: long | F35: 25 | H35: 0.25328 | I35: 0.26013 | J35: close | K35: 67.61 | R35: closed | S35: Bybit | T35: pnl_share_card | U35: Card label reads 'Exit Price' (closed). Per message this was a journal trade held for ~10 days and closed out of impatience despite conviction it would 'blow up'. | V35: Also closing this trade from Journals, 100% this is gonna blow up but I have been holding for 10 days, its getting annoying. https://discord.com/channels/1042855255089623100/1496387902140321885/1497875763314298912 @Paladin Notify | W35: 016_2026-05-09_045210_Screenshot_20260509-063054.png | X35: high | Y35: https://discord.com/channels/1042855255089623100/1501271173588193290/1502488322143162518
A36: 2026-05-09 | B36: 06:06:56 | C36: BTCUSDT | D36: BTC | E36: long | F36: 100 | H36: 79764.4 | I36: 80341.2 | J36: close | K36: 72.31 | R36: closed | S36: Bybit | T36: pnl_share_card | U36: Card label reads 'Exit Price' (closed). Same position shown open in image 014 (current 80,333.90 / +67.25%). | V36: Closing BTC @ 80.4k @Paladin Notify | W36: 017_2026-05-09_060656_Screenshot_20260509-080604.png | X36: high | Y36: https://discord.com/channels/1042855255089623100/1501271173588193290/1502507137337786561
A37: 2026-05-10 | B37: 18:45:44 | C37: ETHUSDT | D37: ETH | E37: long | F37: 100 | H37: 2311.73 | I37: 2340.53 | J37: close | K37: 124.58 | R37: closed | S37: Bybit | T37: pnl_share_card | U37: Card label reads 'Exit Price' (closed). Described in the message as a weekend scalp. | V37: Alright guys good enough for a weekend scalp, closing it here! @Paladin Notify | W37: 018_2026-05-10_184544_Screenshot_20260510-204502.png | X37: high | Y37: https://discord.com/channels/1042855255089623100/1501271173588193290/1503060481118568578
A38: 2026-05-10 | B38: 21:01:23 | C38: AVNTUSDT | D38: AVNT | E38: long | F38: 50 | H38: 0.15851 | I38: 0.16709 | J38: mark | K38: 246.69 | R38: open | S38: Bybit | T38: pnl_share_card | U38: Card label reads 'Current Price' (position still open). Per message this is TP1 with a full close planned at 0.1746 (not shown on the card). Same position as image 011 (then at 0.16787 / +265.55%). | V38: AVNT TP1 here, fully close @ 0.1746 @Paladin Notify | W38: 019_2026-05-10_210123_Screenshot_20260510-224944.png | X38: high | Y38: https://discord.com/channels/1042855255089623100/1501271173588193290/1503094618345181387
A39: 2026-05-10 | B39: 22:10:30 | C39: ZROUSDT | D39: ZRO | E39: long | F39: 50 | H39: 1.4744 | I39: 1.53 | J39: mark | K39: 178.94 | R39: open | S39: Bybit | T39: pnl_share_card | U39: Card label reads 'Current Price' (position still open). Per message he took 25% off here and plans a full exit around 1.55+ (not shown on the card). Same position as image 013 (then at 1.4849 / +34.43%). | V39: 25% here, fully exit around 1.55+ Will update if I see weakness @Paladin Notify | W39: 020_2026-05-10_221030_Screenshot_20260511-000006.png | X39: high | Y39: https://discord.com/channels/1042855255089623100/1501271173588193290/1503112014283673735
... A42: 2026-05-11 | B42: 09:12:24 | C42: ZROUSDT | D42: ZRO | E42: long | F42: 50 | H42: 1.4772 | I42: 1.5369 | J42: mark | K42: 189.93 | R42: open | S42: Bybit | T42: pnl_share_card | U42: Bybit rocket share card; price label is 'Current Price' (position open). No date, size or USD PnL shown. | V42: And the streak continues, 20% here not moving SL to entry. @Paladin Notify | W42: 023_2026-05-11_091224_17784798553272.jpg | X42: high | Y42: https://discord.com/channels/1042855255089623100/1501271173588193290/1503278586050777149
A43: 2026-05-11 | B43: 09:13:29 | C43: BTCUSDT | D43: BTC | E43: long | F43: 150 | K43: 51.78 | R43: open | S43: Blofin | T43: pnl_share_card | U43: Header reads 'Unrealized PnL' (open position). Card is cropped to the top part: entry price, mark price, date and size are not visible. 150X leverage and the card layout (pair | Long | 150X with a character figure on the right) match Blofin share cards. | V43: I have started to scale in BTC long as well will give out once I'm confident enough For an idea I'm long since 80.6k SL @ 79.5k | W43: 024_2026-05-11_091329_Screenshot_20260511-111236.png | X43: medium | Y43: https://discord.com/channels/1042855255089623100/1501271173588193290/1503278860400332892
A44: 2026-05-11 | B44: 12:32:58 | C44: ZROUSDT | D44: ZRO | E44: long | F44: 50 | H44: 1.4772 | I44: 1.5457 | J44: mark | K44: 215.72 | R44: open | S44: Bybit | T44: pnl_share_card | U44: Bybit rocket share card; price label is 'Current Price' (card generated while the position was still open, even though the message announces the TP was hit). Same entry 1.4772 as the earlier ZRO card. | V44: ZRO TP hit @Paladin Notify | W44: 025_2026-05-11_123258_17784899060412.jpg | X44: high | Y44: https://discord.com/channels/1042855255089623100/1501271173588193290/1503329058543370330
A45: 2026-05-11 | B45: 19:33:50 | C45: BTCUSDT | D45: BTC | E45: long | F45: 100 | H45: 80914.2 | I45: 81798.7 | J45: close | K45: 109.31 | R45: closed | S45: Bybit | T45: pnl_share_card | U45: Bybit rocket share card with 'Exit Price' label (closed trade). No date, size or USD PnL shown. | W45: 026_2026-05-11_193350_Screenshot_20260511-213326.png | X45: high | Y45: https://discord.com/channels/1042855255089623100/1501271173588193290/1503434974102163536
A46: 2026-05-12 | B46: 06:19:25 | C46: STABLEUSDT | D46: STABLE | E46: long | F46: 25 | H46: 0.03459 | I46: 0.036652 | J46: mark | K46: 144.12 | R46: open | S46: Bybit | T46: pnl_share_card | U46: Bybit rocket share card; price label is 'Current Price' (position open). OCR missed the ROI value; the card clearly shows +144.12%. | V46: TP1 @ 0.03737 | W46: 027_2026-05-12_061925_Screenshot_20260512-081814.png | X46: high | Y46: https://discord.com/channels/1042855255089623100/1501271173588193290/1503597441675558924
A47: 2026-05-12 | B47: 06:49:52 | C47: STABLEUSDT | D47: STABLE | E47: long | F47: 25 | H47: 0.03459 | I47: 0.03737 | J47: close | K47: 200.92 | R47: closed | S47: Bybit | T47: pnl_share_card | U47: Bybit rocket share card with 'Exit Price' label (closed). Exit 0.037370 equals the TP1 level he had announced (0.03737). | V47: I accidentally closed 100% here but 0.04 TP is valid, take at least 50% as this is resistance. @Paladin Notify | W47: 028_2026-05-12_064952_Screenshot_20260512-084847.png | X47: high | Y47: https://discord.com/channels/1042855255089623100/1501271173588193290/1503605103997882428
A48: 2026-05-12 | B48: 15:11:23 | C48: STABLEUSDT | D48: STABLE | E48: long | H48: 0.03453 | I48: 0.03884 | J48: last | L48: 43.1294 | M48: 10,000 | R48: open | S48: MEXC | T48: chart | U48: MEXC app: dashed green position line at 0.03453 with tag 'PNL +43.1294 | 10,000' (10,000 = contracts/STABLE size). Side inferred from positive PnL with price above the entry line; leverage not shown on the chart. Exit price = Last Price 0.03884 shown at the top. A red 'S' (sell) marker sits on the big green impulse candle near ~0.0378, likely a partial sell / TP fill. | V48: Guys I would like to clarify something since I shared this screenshot it says DEMO, I got like 5 DMs saying I'm trading on DEMO It is CFT funded account so it shows demo, I trade on other exchanges with real money. Even if it's demo are the trades hitting TPs or not? Just wanted to clarify it once. | W48: 030_2026-05-12_151123_Screenshot_20260512-170605.png | X48: high | Y48: https://discord.com/channels/1042855255089623100/1501271173588193290/1503731313855692950
A49: 2026-05-12 | B49: 15:11:23 | C49: STABLEUSDT | D49: STABLE | E49: long | F49: 20 | H49: 0.03453 | I49: 0.03886 | J49: mark | K49: 248.34 | L49: 43.2294 | R49: open | S49: MEXC | T49: pnl_share_card | U49: MEXC share card ('0% Liquidity NO.1' graphic). Price label is 'Fair Price' (MEXC's mark price) so the position was still open. PnL shown as +43.2294 USDT. No date shown. | V49: Guys I would like to clarify something since I shared this screenshot it says DEMO, I got like 5 DMs saying I'm trading on DEMO It is CFT funded account so it shows demo, I trade on other exchanges with real money. Even if it's demo are the trades hitting TPs or not? Just wanted to clarify it once. | W49: 031_2026-05-12_151123_Screenshot_20260512-170852.png | X49: high | Y49: https://discord.com/channels/1042855255089623100/1501271173588193290/1503731313855692950
A50: 2026-05-13 | B50: 06:13:16 | C50: STABLEUSDT | D50: STABLE | E50: long | F50: 20 | K50: 231.02 | R50: closed | S50: MEXC | T50: pnl_share_card | U50: Cropped MEXC 'Closed PNL' share card (same layout as the MEXC open-position card). Only header, pair, side, leverage and ROI are visible; entry/close price, USDT PnL and date are cut off. Decorative mini line graphic with green 'B' (buy) and red 'S' (sell) markers on the right. | V50: STABLE hit full TP of 0.04, 20% unleveraged move! @Paladin Notify | W50: 032_2026-05-13_061316_Screenshot_20260513-081109.png | X50: medium | Y50: https://discord.com/channels/1042855255089623100/1501271173588193290/1503958280999796848
A51: 2026-05-13 | B51: 12:11:15 | C51: SOLUSDT | D51: SOL | E51: long | F51: 100 | H51: 95.53 | I51: 95.7 | J51: close | K51: 17.79 | R51: closed | S51: Bybit | T51: pnl_share_card | U51: Bybit rocket share card with 'Exit Price' label (closed). Small move (0.17) amplified by 100x leverage. | V51: Closing SOL here personally, I want to be on the safe side and keep my streak. We already have 3 longs and they are running good enough, expect TPs soon InshaAllah! @Paladin Notify | W51: 033_2026-05-13_121115_Screenshot_20260513-140807.png | X51: high | Y51: https://discord.com/channels/1042855255089623100/1501271173588193290/1504048372351504406
A52: 2026-05-14 | B52: 17:30:30 | C52: SOLUSDT | D52: SOL | E52: long | F52: 100 | H52: 91.05 | I52: 91.46 | J52: close | K52: 45.03 | R52: closed | S52: Bybit | T52: pnl_share_card | U52: Bybit rocket share card with 'Exit Price' label (closed). No date, size or USD PnL shown. | V52: Closing SOL and XRP in minor profits BTC avg 79.2k with a DCA running in heavy profits @Paladin Notify | W52: 034_2026-05-14_173030_Screenshot_20260514-192753.png | X52: high | Y52: https://discord.com/channels/1042855255089623100/1501271173588193290/1504491099048251594
A53: 2026-05-14 | B53: 17:30:30 | C53: XRPUSDT | D53: XRP | E53: long | F53: 100 | H53: 1.4497 | I53: 1.4531 | J53: close | K53: 23.45 | R53: closed | S53: Bybit | T53: pnl_share_card | U53: Bybit rocket share card with 'Exit Price' label (closed). No date, size or USD PnL shown. | V53: Closing SOL and XRP in minor profits BTC avg 79.2k with a DCA running in heavy profits @Paladin Notify | W53: 035_2026-05-14_173030_Screenshot_20260514-192733.png | X53: high | Y53: https://discord.com/channels/1042855255089623100/1501271173588193290/1504491099048251594
...

Sheet Images
A1: # | B1: Date | C1: Time | D1: Trading related | E1: Image type | F1: Platform | G1: Trades in image | H1: Symbols | I1: Chart timeframe | J1: Chart indicators | K1: Chart levels / drawings | L1: What the chart shows | M1: Description | N1: Text visible in image | O1: Message posted with image | P1: Date/time printed on image | Q1: Confidence | R1: Issues | S1: Image file | T1: Duplicate of | U1: Discord link
A2: 1 | B2: 2026-05-06 | C2: 23:47:41 | D2: yes | E2: discord_message_screenshot | F2: Discord | G2: 24 | H2: ALGOUSDT, ASTERUSDT, AXSUSDT, BTCUSDT, ETHUSDT, HYPEUSDT, IRYSUSDT, PEPEUSDT, SOLUSDT | M2: Screenshot of his own Discord recap message listing 25 journal trades by ticker (22 wins, 3 break-even, 0 losses) with a party emoji, followed by an embedded Binance Futures USDⓈ-M 'My Futures PnL' card showing Cumulative PNL % +90.94% for the period 2026-04-30 to 2026-05-07, a small gold cumulative-PnL sparkline (flat, dip, spike, dip, slight rise) and Win Rate 100.00%. Shows he is journaling on Binance Futures and trades mostly BTC with occasional alts (ETH, ASTER, AXS, IRYS, HYPE, PEPE, SOL, ALGO). | N2: So far, 25 trades 22 Winning trades (ASTER, AXS, IRYS, BTC, BTC, BTC, ETH, HYPE, PEPE, ETH, BTC, BTC, BTC, BTC, BTC, ETH, BTC, BTC, BTC, BTC, BTC) 3 BE trades (SOL, ALGO, BTC) 0 Loss (edited) 🎉 [Binance share card] My Futures PnL Cumulative PNL % Period: 2026-04-30 - 2026-05-07 +90.94% Win Rate 100.00% BINANCE FUTURES | USDⓈ-M Referral Code 550295426 | O2: I have been trading for the past month in journals and here's my progress so far **25** trades **22** Wins **3** BE **0** loss Can track it all in the journal -> https://discord.com/channels/1042855255089623100/1496387902140321885/1501536396127633418 @Paladin Notify | P2: Period: 2026-04-30 - 2026-05-07 | Q2: high | R2: Author name and message time are cropped out. The recap says 22 winning trades but only 21 tickers are listed in the parentheses (24 tickers total vs. 25 trades stated); trade entries reflect the 24 tickers actually listed. Tickers are given as base assets only (no quote currency); the sparkline is a PnL curve, not a price chart. | S2: 001_2026-05-06_234741_Screenshot_20260507-014653.png | U2: https://discord.com/channels/1042855255089623100/1501271173588193290/1501686917828448277
A3: 2 | B3: 2026-05-08 | C3: 13:48:41 | D3: yes | E3: open_positions_screenshot | F3: unknown | G3: 1 | H3: BTCUSDT | M3: A tiny crop of an exchange position/order field showing only 'Entry Price (USDT) 79,564.80' (dark UI, label style resembling Bybit's positions tab). Posted as BTC 'started moving' to show his entry level while suggesting followers take 20% off at 80.5k. | N3: Entry Price (USDT) 79,564.80 | O3: BTC started moving, you can take 20% @ 80.5k if you want, I'll update whenever I close! | Q3: medium | R3: Image is a small crop: no symbol, side, leverage, size, PnL or exchange branding visible; symbol/side inferred from message context only. Platform not identifiable with certainty. | S3: 002_2026-05-08_134841_Screenshot_20260508-1547142.png | U3: https://discord.com/channels/1042855255089623100/1501271173588193290/1502260952098279615
A4: 3 | B4: 2026-05-08 | C4: 18:44:20 | D4: yes | E4: pnl_share_card | F4: Bybit | G4: 1 | H4: UNIUSDT | M4: Top portion of a Bybit-style PnL share card for a UNIUSDT 50X long showing ROI +101.21%; posted when he closed 50% of the UNI position as the 'first win'. | N4: UNIUSDT Long 50.0X ROI +101.21% | O4: Okay let's treat as our first win Closing 50% UNI for 0.7 R move, I'll take personally fully TP @ 3.7 You can hold till 4 SL @ BE 3.46 @Paladin Notify | Q4: medium | R4: Card is cropped below the ROI: entry/exit prices, price-type label and exchange logo are not visible. Platform identified from the card style (identical to his other Bybit cards), not from a visible logo. | S4: 003_2026-05-08_184420_Screenshot_20260508-203512.png | U4: https://discord.com/channels/1042855255089623100/1501271173588193290/1502335355628687451
A5: 4 | B5: 2026-05-08 | C5: 19:41:13 | D5: yes | E5: chart | F5: Bybit | G5: 0 | I5: 15m | J5: EMA7 (3.614); EMA14 (3.577); EMA28 (3.537); volume with MA5 (138.12K) and MA10 (124.64K) | K5: exchange auto high marker 3.698 at the current candle; exchange auto low marker 3.392 near 13:15; current price line 3.687 with countdown 05:13; no user drawings | L5: UNIUSDT 15m in a vertical breakout: after grinding up along the EMAs all day, price went parabolic from ~3.47 around 18:45 to a new 24h high of 3.698 with a big volume spike on the last candles; EMAs stacked bullishly. He posted this as he exited UNI fully at 3.7, i.e. selling into the spike. | M5: Bybit app (Demo Trading watermark) 15m candlestick chart of UNIUSDT, up +7.52% on the day, showing a parabolic breakout to the 24h high 3.698 with last price 3.687 and a volume spike. Posted with his message that he is fully out of UNI at 3.7 for ~1.4R and expects $4 by the coming weekend/week. | N5: UNIUSDT ▾ +7.52% MM 0.65% Chart Overview Data Feed Last Traded Price ▾ 3.687 Mark Price 3.689 24h High 3.698 24h Low 3.383 24h Turnover 13.02M Time 15m 1h 4h 1D More ▾ | Depth EMA7: 3.614 EMA14: 3.577 EMA28: 3.537 3.698 3.687 05:13 3.621 3.545 3.468 3.392 BYBIT Demo Trading 10:30 13:15 16:00 18:45 21:30 00:15 VOLUME: 184.08K MA5: 138.12K MA10: 124.64K 298.48K | O5: Well UNI blew up, I'm fully out here @ 3.7 for around 1.4 R Think we see 4$ by coming weekend/week @Paladin Notify | P5: chart time axis 10:30, 13:15, 16:00, 18:45, 21:30, 00:15 (no date shown); candle countdown 05:13 | Q5: high | R5: The green 'MM 0.65%' badge next to the symbol is transcribed verbatim but its meaning is not stated on screen. Bottom of the volume pane is cut off. | S5: 004_2026-05-08_194113_Screenshot_20260508-213947.png | U5: https://discord.com/channels/1042855255089623100/1501271173588193290/1502349669571891250
A6: 5 | B6: 2026-05-09 | C6: 02:01:21 | D6: yes | E6: chart | F6: Bybit | G6: 0 | I6: 4h | J6: EMA7 (90.319); EMA14 (89.347); EMA28 (88.070) | K6: exchange auto high marker 92.760 at the latest candles; exchange auto low marker 82.740 near 05/01-05/02; current price line 92.240 with countdown 01:06:14; no user drawings | L6: SOLUSDT 4h in a steady uptrend from ~82.74 on May 1: base-building, then a strong impulse on May 5-6 to ~90, consolidation around 88-90 along EMA7/EMA14, and a large green 4h candle to a new 24h high 92.760 with the current candle slightly red at 92.240. Posted as one of the alts he said were 'popping off'. | M6: Bybit (Demo Trading) 4h chart of SOLUSDT, +4.79% on the day, breaking out to a 24h high of 92.760 with price at 92.240 above bullishly stacked EMAs. One of four alt charts he posted to show the coins he had mentioned were all moving up. | N6: SOLUSDT ▾ +4.79% MM 0.80% Chart Overview Data Feed Last Traded Price ▾ 92.240 Mark Price 92.240 24h High 92.760 24h Low 87.560 24h Turnover 907.66M Time 15m 1h 4h 1D More ▾ | Depth EMA7: 90.319 EMA14: 89.347 EMA28: 88.070 92.760 92.240 01:06:14 90.255 87.750 85.245 82.740 BYBIT Demo Trading 05/01 17:00 05/03 13:00 05/05 09:00 05/07 05:00 05/09 01:00 05/10 21 | O6: Look at them go, every ALT I mentioned here just popping off even ASTER started moving 🤣 Usually I'm already in too many trades and have to limit myself for giving positions because I feel like people don't care about risk management and jump in all in. But if I ever mention a coin and you can do some analysis, check them out! | P6: chart time axis 05/01 17:00, 05/03 13:00, 05/05 09:00, 05/07 05:00, 05/09 01:00, 05/10 21… (cut); candle countdown 01:06:14 | Q6: high | R6: Last time-axis label is cut off ('05/10 21'). 'MM 0.80%' badge meaning not stated on screen. | S6: 005_2026-05-09_020121_Screenshot_20260509-035346.png | U6: https://discord.com/channels/1042855255089623100/1501271173588193290/1502445332355878943
A7: 6 | B7: 2026-05-09 | C7: 02:01:21 | D7: yes | E7: chart | F7: Bybit | G7: 0 | I7: 1D | J7: EMA7 (1.4300); EMA14 (1.3897); EMA28 (1.3631) | K7: exchange auto high marker 1.6069 at the current daily candle; exchange auto low marker 1.1285 near 03/29-03/30; current price line 1.5902 with countdown 01:05:31; no user drawings | L7: NEARUSDT daily: bottom at 1.1285 in late March, rally to ~1.45 by mid-April, a pullback into early May toward ~1.25 (below the EMAs), then two very large green daily candles breaking out to a new high of 1.6069 with price at 1.5902 well above all EMAs. Posted as an example of alts he mentioned 'popping off'. | M7: Bybit (Demo Trading) daily chart of NEARUSDT, +8.81% on the day, showing a two-day vertical breakout from ~1.25 to 1.6069 with price at 1.5902. Part of his 'look at them go' batch of alt charts. | N7: NEARUSDT ▾ +8.81% MM 0.80% Chart Overview Data Feed Last Traded Price ▾ 1.5902 Mark Price 1.5902 24h High 1.6069 24h Low 1.4548 24h Turnover 64.14M Time 15m 1h 4h 1D More ▾ | Depth EMA7: 1.4300 EMA14: 1.3897 EMA28: 1.3631 1.6069 1.5902 01:05:31 1.4873 1.3677 1.2481 1.1285 BYBIT Demo Trading 03/25 04/05 04/16 04/27 05/08 05/1 | O7: Look at them go, every ALT I mentioned here just popping off even ASTER started moving 🤣 Usually I'm already in too many trades and have to limit myself for giving positions because I feel like people don't care about risk management and jump in all in. But if I ever mention a coin and you can do some analysis, check them out! | P7: chart time axis 03/25, 04/05, 04/16, 04/27, 05/08, 05/1… (cut); candle countdown 01:05:31 | Q7: high | R7: Last time-axis label is cut off. 'MM 0.80%' badge meaning not stated on screen. | S7: 006_2026-05-09_020121_Screenshot_20260509-035429.png | U7: https://discord.com/channels/1042855255089623100/1501271173588193290/1502445332355878943
A8: 7 | B8: 2026-05-09 | C8: 02:01:21 | D8: yes | E8: chart | F8: Bybit | G8: 0 | I8: 4h | J8: EMA7 (0.0020866); EMA14 (0.0020354); EMA28 (0.0019720) | K8: exchange auto high marker 0.0021932 at the current candles; exchange auto low marker 0.0017500 at the far left of the visible range; current price line 0.0021615 with countdown 01:05:12; no user drawings | L8: PUMPFUNUSDT 4h in a clean stair-step uptrend from 0.00175 to a 24h high of 0.0021932: consolidation, impulse, shallow pullbacks holding EMA7/EMA14, then a strong green push; current candle slightly red at 0.0021615 above all EMAs. Posted as an example of alts he mentioned 'popping off'. | M8: Bybit (Demo Trading) 4h chart of PUMPFUNUSDT, +9.37% on the day, in a steady uptrend to a new high 0.0021932 with price at 0.0021615. Part of his 'look at them go' batch of alt charts. | N8: PUMPFUNUSDT ▾ +9.37% MM 0.80% Chart Overview Data Feed Last Traded Price ▾ 0.0021615 Mark Price 0.0021615 24h High 0.0021932 24h Low 0.0019738 24h Turnover 19.85M Time 15m 1h 4h 1D More ▾ | Depth EMA7: 0.0020866 EMA14: 0.0020354 EMA28: 0.0019720 0.0021932 0.0021615 01:05:12 0.0020824 0.0019716 0.0018608 0.0017500 BYBIT Demo Trading | O8: Look at them go, every ALT I mentioned here just popping off even ASTER started moving 🤣 Usually I'm already in too many trades and have to limit myself for giving positions because I feel like people don't care about risk management and jump in all in. But if I ever mention a coin and you can do some analysis, check them out! | P8: candle countdown 01:05:12 (time axis cut off) | Q8: high | R8: Time axis is cut off at the bottom, so no dates are visible. 'MM 0.80%' badge meaning not stated on screen. | S8: 007_2026-05-09_020121_Screenshot_20260509-035449.png | U8: https://discord.com/channels/1042855255089623100/1501271173588193290/1502445332355878943
A9: 8 | B9: 2026-05-09 | C9: 02:01:21 | D9: yes | E9: chart | F9: Bybit | G9: 0 | I9: 4h | J9: EMA7 (0.6746); EMA14 (0.6727); EMA28 (0.6719) | K9: exchange auto high marker 0.6992 at the current candle (long upper wick); exchange auto low marker 0.6487 near 05/01-05/02; current price line 0.6893 with countdown 01:04:49; no user drawings | L9: ASTERUSDT 4h: a choppy week-long range roughly 0.655-0.70 with the three EMAs flat and bunched (0.6719-0.6746), a flush to ~0.655 on May 8, then a sharp two-candle rally that spiked to 0.6992 and left a long upper wick with price back at 0.6893. He pointed out that 'even ASTER started moving'. | M9: Bybit (Demo Trading) 4h chart of ASTERUSDT, +4.50% on the day, showing a ranging market that just spiked to 0.6992 (long upper wick) with price at 0.6893. Last of four alt charts posted to show the coins he had mentioned were moving. | N9: ASTERUSDT ▾ +4.50% MM 0.80% Chart Overview Data Feed Last Traded Price ▾ 0.6893 Mark Price 0.6894 24h High 0.6992 24h Low 0.6581 24h Turnover 12.81M Time 15m 1h 4h 1D More ▾ | Depth EMA7: 0.6746 EMA14: 0.6727 EMA28: 0.6719 0.6992 0.6893 01:04:49 0.6739 0.6613 0.6487 BYBIT Demo Trading 05/01 17:00 05/03 13:00 05/05 09:00 05/07 05:00 05/09 01:00 05/10 21 | O9: Look at them go, every ALT I mentioned here just popping off even ASTER started moving 🤣 Usually I'm already in too many trades and have to limit myself for giving positions because I feel like people don't care about risk management and jump in all in. But if I ever mention a coin and you can do some analysis, check them out! | P9: chart time axis 05/01 17:00, 05/03 13:00, 05/05 09:00, 05/07 05:00, 05/09 01:00, 05/10 21… (cut); candle countdown 01:04:49 | Q9: high | R9: Last time-axis label is cut off. 'MM 0.80%' badge meaning not stated on screen. | S9: 008_2026-05-09_020121_Screenshot_20260509-035511.png | U9: https://discord.com/channels/1042855255089623100/1501271173588193290/1502445332355878943
A10: 9 | B10: 2026-05-09 | C10: 04:45:42 | D10: yes | E10: pnl_share_card | F10: Bybit | G10: 1 | H10: KERNELUSDT | M10: Bybit PnL share card (rocket graphic) for an open KERNELUSDT 20X long: entry 0.06454, current price 0.06615, ROI +49.35%. Posted as 'KERNEL TP1 here' with next TP at 0.0673. | N10: KERNELUSDT Long 20.0X ROI +49.35% Entry Price 0.06454 Current Price 0.06615 BYBIT | O10: KERNEL TP1 here, next TP @ 0.0673 @Paladin Notify | Q10: high | S10: 009_2026-05-09_044542_Screenshot_20260509-064308.png | U10: https://discord.com/channels/1042855255089623100/1501271173588193290/1502486692232298586
A11: 10 | B11: 2026-05-09 | C11: 04:48:32 | D11: yes | E11: pnl_share_card | F11: Bybit | G11: 1 | H11: KERNELUSDT | M11: Bybit PnL share card for an open KERNELUSDT 20X long, entry 0.06454, current 0.06615, ROI +49.35% — a duplicate of image 009 re-posted with the 'all trades running in good profits, take TP whenever you want' message. | N11: KERNELUSDT Long 20.0X ROI +49.35% Entry Price 0.06454 Current Price 0.06615 BYBIT | O11: All trades running in good profits, take TP whenever you want, don't let them round trip. I'll update when I close. | Q11: high | R11: Duplicate of image 009. | S11: 010_2026-05-09_044832_Screenshot_20260509-064308.png | T11: 009_2026-05-09_044542_Screenshot_20260509-064308.png | U11: https://discord.com/channels/1042855255089623100/1501271173588193290/1502487407654862971
A12: 11 | B12: 2026-05-09 | C12: 04:48:32 | D12: yes | E12: pnl_share_card | F12: Bybit | G12: 1 | H12: AVNTUSDT | M12: Bybit PnL share card for an open AVNTUSDT 50X long: entry 0.15851, current price 0.16787, ROI +265.55%. Part of the batch of running trades he posted telling followers to take TP whenever they want and not let them round-trip. | N12: AVNTUSDT Long 50.0X ROI +265.55% Entry Price 0.15851 Current Price 0.16787 BYBIT | O12: All trades running in good profits, take TP whenever you want, don't let them round trip. I'll update when I close. | Q12: high | S12: 011_2026-05-09_044832_Screenshot_20260509-064552.png | U12: https://discord.com/channels/1042855255089623100/1501271173588193290/1502487407654862971
A13: 12 | B13: 2026-05-09 | C13: 04:48:32 | D13: yes | E13: pnl_share_card | F13: Bybit | G13: 1 | H13: SNXUSDT | M13: Bybit PnL share card for an open SNXUSDT 25X long: entry 0.3545, current price 0.3727, ROI +118.67%. Part of the batch of running trades posted with 'take TP whenever you want, don't let them round trip'. | N13: SNXUSDT Long 25.0X ROI +118.67% Entry Price 0.3545 Current Price 0.3727 BYBIT | O13: All trades running in good profits, take TP whenever you want, don't let them round trip. I'll update when I close. | Q13: high | S13: 012_2026-05-09_044832_Screenshot_20260509-064638.png | U13: https://discord.com/channels/1042855255089623100/1501271173588193290/1502487407654862971
A14: 13 | B14: 2026-05-09 | C14: 04:48:32 | D14: yes | E14: pnl_share_card | F14: Bybit | G14: 1 | H14: ZROUSDT | M14: Bybit PnL share card for an open ZROUSDT 50X long: entry 1.4744, current price 1.4849, ROI +34.43%. Part of the batch of running trades posted on May 9. | N14: ZROUSDT Long 50.0X ROI +34.43% Entry Price 1.4744 Current Price 1.4849 BYBIT | O14: All trades running in good profits, take TP whenever you want, don't let them round trip. I'll update when I close. | Q14: high | S14: 013_2026-05-09_044832_Screenshot_20260509-064657.png | U14: https://discord.com/channels/1042855255089623100/1501271173588193290/1502487407654862971
A15: 14 | B15: 2026-05-09 | C15: 04:48:32 | D15: yes | E15: pnl_share_card | F15: Bybit | G15: 1 | H15: BTCUSDT | M15: Bybit PnL share card for an open BTCUSDT 100X long: entry 79,764.40, current price 80,333.90, ROI +67.25%. Part of the batch of running trades posted on May 9. | N15: BTCUSDT Long 100.0X ROI +67.25% Entry Price 79,764.40 Current Price 80,333.90 BYBIT | O15: All trades running in good profits, take TP whenever you want, don't let them round trip. I'll update when I close. | Q15: high | S15: 014_2026-05-09_044832_Screenshot_20260509-064717.png | U15: https://discord.com/channels/1042855255089623100/1501271173588193290/1502487407654862971
A16: 15 | B16: 2026-05-09 | C16: 04:48:32 | D16: yes | E16: pnl_share_card | F16: Bybit | G16: 1 | H16: UNIUSDT | M16: Bybit PnL share card for a closed UNIUSDT 50X long: entry 3.458, exit 3.528, ROI +101.21%. Re-posted within the May 9 batch of trade cards; it documents the earlier UNI partial close. | N16: UNIUSDT Long 50.0X ROI +101.21% Entry Price 3.458 Exit Price 3.528 BYBIT | O16: All trades running in good profits, take TP whenever you want, don't let them round trip. I'll update when I close. | Q16: high | S16: 015_2026-05-09_044832_Screenshot_20260509-063448.png | U16: https://discord.com/channels/1042855255089623100/1501271173588193290/1502487407654862971
A17: 16 | B17: 2026-05-09 | C17: 04:52:10 | D17: yes | E17: pnl_share_card | F17: Bybit | G17: 1 | H17: SYRUPUSDT | M17: Bybit PnL share card for a closed SYRUPUSDT 25X long: entry 0.25328, exit 0.26013, ROI +67.61%. Posted when closing this Journals trade after holding it 10 days because it was 'getting annoying'. | N17: SYRUPUSDT Long 25.0X ROI +67.61% Entry Price 0.25328 Exit Price 0.26013 BYBIT | O17: Also closing this trade from Journals, 100% this is gonna blow up but I have been holding for 10 days, its getting annoying. https://discord.com/channels/1042855255089623100/1496387902140321885/1497875763314298912 @Paladin Notify | Q17: high | S17: 016_2026-05-09_045210_Screenshot_20260509-063054.png | U17: https://discord.com/channels/1042855255089623100/1501271173588193290/1502488322143162518
A18: 17 | B18: 2026-05-09 | C18: 06:06:56 | D18: yes | E18: pnl_share_card | F18: Bybit | G18: 1 | H18: BTCUSDT | M18: Bybit PnL share card for a closed BTCUSDT 100X long: entry 79,764.40, exit 80,341.20, ROI +72.31%. Posted with 'Closing BTC @ 80.4k'. | N18: BTCUSDT Long 100.0X ROI +72.31% Entry Price 79,764.40 Exit Price 80,341.20 BYBIT | O18: Closing BTC @ 80.4k @Paladin Notify | Q18: high | S18: 017_2026-05-09_060656_Screenshot_20260509-080604.png | U18: https://discord.com/channels/1042855255089623100/1501271173588193290/1502507137337786561
A19: 18 | B19: 2026-05-10 | C19: 18:45:44 | D19: yes | E19: pnl_share_card | F19: Bybit | G19: 1 | H19: ETHUSDT | M19: Bybit PnL share card for a closed ETHUSDT 100X long: entry 2,311.73, exit 2,340.53, ROI +124.58%. Posted on Sunday May 10 as 'good enough for a weekend scalp, closing it here'. | N19: ETHUSDT Long 100.0X ROI +124.58% Entry Price 2,311.73 Exit Price 2,340.53 BYBIT | O19: Alright guys good enough for a weekend scalp, closing it here! @Paladin Notify | Q19: high | S19: 018_2026-05-10_184544_Screenshot_20260510-204502.png | U19: https://discord.com/channels/1042855255089623100/1501271173588193290/1503060481118568578
A20: 19 | B20: 2026-05-10 | C20: 21:01:23 | D20: yes | E20: pnl_share_card | F20: Bybit | G20: 1 | H20: AVNTUSDT | M20: Bybit PnL share card for the still-open AVNTUSDT 50X long: entry 0.15851, current price 0.16709, ROI +246.69%. Posted as 'AVNT TP1 here, fully close @ 0.1746'. | N20: AVNTUSDT Long 50.0X ROI +246.69% Entry Price 0.15851 Current Price 0.16709 BYBIT | O20: AVNT TP1 here, fully close @ 0.1746 @Paladin Notify | Q20: high | S20: 019_2026-05-10_210123_Screenshot_20260510-224944.png | U20: https://discord.com/channels/1042855255089623100/1501271173588193290/1503094618345181387
A21: 20 | B21: 2026-05-10 | C21: 22:10:30 | D21: yes | E21: pnl_share_card | F21: Bybit | G21: 1 | H21: ZROUSDT | M21: Bybit PnL share card for the still-open ZROUSDT 50X long: entry 1.4744, current price 1.5300, ROI +178.94%. Posted with '25% here, fully exit around 1.55+, will update if I see weakness'. | N21: ZROUSDT Long 50.0X ROI +178.94% Entry Price 1.4744 Current Price 1.5300 BYBIT | O21: 25% here, fully exit around 1.55+ Will update if I see weakness @Paladin Notify | Q21: high | S21: 020_2026-05-10_221030_Screenshot_20260511-000006.png | U21: https://discord.com/channels/1042855255089623100/1501271173588193290/1503112014283673735
A22: 21 | B22: 2026-05-10 | C22: 23:33:31 | D22: yes | E22: pnl_share_card | F22: Bybit | G22: 1 | H22: SNXUSDT | M22: Bybit PnL share card for an open SNXUSDT 25x long at +55.80% ROI (entry 0.3545, current 0.3626). Posted with the message that he is closing SNX in some profit because he expects a pullback and plans to reopen after Monday. | N22: SNXUSDT Long 25.0X ROI +55.80% Entry Price 0.3545 Current Price 0.3626 BYBIT | O22: Closing SNX in some profits, we're gonna have a pullback will open again after Monday @Paladin Notify | Q22: high | S22: 021_2026-05-10_233331_Screenshot_20260511-013234.png | U22: https://discord.com/channels/1042855255089623100/1501271173588193290/1503132904983756810
A23: 22 | B23: 2026-05-11 | C23: 03:58:37 | D23: yes | E23: pnl_share_card | F23: Bybit | G23: 1 | H23: BTCUSDT | M23: Bybit share card of a closed BTCUSDT 100x short: entry 82,202.80, exit 81,302.90, +109.47% ROI. Posted as 'TPed, fast top short, closed' - a quick counter-trend short at a local top that he took profit on. | N23: BTCUSDT Short 100.0X ROI +109.47% Entry Price 82,202.80 Exit Price 81,302.90 BYBIT | O23: TPed, fast top short, closed. @Paladin Notify | Q23: high | S23: 022_2026-05-11_035837_Screenshot_20260511-055757.png | U23: https://discord.com/channels/1042855255089623100/1501271173588193290/1503199620715642910
A24: 23 | B24: 2026-05-11 | C24: 09:12:24 | D24: yes | E24: pnl_share_card | F24: Bybit | G24: 1 | H24: ZROUSDT | M24: Bybit share card for an open ZROUSDT 50x long at +189.93% ROI (entry 1.4772, current 1.5369). Message says the streak continues, 20% here, and that he is not moving the SL to entry - i.e. he keeps the original stop rather than protecting the trade at breakeven. | N24: ZROUSDT Long 50.0X ROI +189.93% Entry Price 1.4772 Current Price 1.5369 BYBIT | O24: And the streak continues, 20% here not moving SL to entry. @Paladin Notify | Q24: high | S24: 023_2026-05-11_091224_17784798553272.jpg | U24: https://discord.com/channels/1042855255089623100/1501271173588193290/1503278586050777149
A25: 24 | B25: 2026-05-11 | C25: 09:13:29 | D25: yes | E25: pnl_share_card | F25: Blofin | G25: 1 | H25: BTCUSDT | M25: Cropped Blofin-style share card showing an open BTCUSDT 150x long with +51.78% unrealized ROI. Message context: he has started scaling into a BTC long (long since 80.6k with SL at 79.5k) and will share it once confident enough. | N25: Unrealized PnL BTCUSDT | Long | 150X +51.78% | O25: I have started to scale in BTC long as well will give out once I'm confident enough For an idea I'm long since 80.6k SL @ 79.5k | Q25: medium | R25: Image is cropped; only header, pair/side/leverage and ROI are visible. Platform identified from card style (no logo visible). | S25: 024_2026-05-11_091329_Screenshot_20260511-111236.png | U25: https://discord.com/channels/1042855255089623100/1501271173588193290/1503278860400332892
A26: 25 | B26: 2026-05-11 | C26: 12:32:58 | D26: yes | E26: pnl_share_card | F26: Bybit | G26: 1 | H26: ZROUSDT | M26: Bybit share card for the ZROUSDT 50x long now at +215.72% ROI (entry 1.4772, current 1.5457), posted with 'ZRO TP hit' - the take-profit level was reached around 1.5457. | N26: ZROUSDT Long 50.0X ROI +215.72% Entry Price 1.4772 Current Price 1.5457 BYBIT | O26: ZRO TP hit @Paladin Notify | Q26: high | S26: 025_2026-05-11_123258_17784899060412.jpg | U26: https://discord.com/channels/1042855255089623100/1501271173588193290/1503329058543370330
A27: 26 | B27: 2026-05-11 | C27: 19:33:50 | D27: yes | E27: pnl_share_card | F27: Bybit | G27: 1 | H27: BTCUSDT | M27: Bybit share card of a closed BTCUSDT 100x long: entry 80,914.20, exit 81,798.70, +109.31% ROI. Posted without text; it is the BTC long he mentioned scaling into earlier that day (long since ~80.6k). | N27: BTCUSDT Long 100.0X ROI +109.31% Entry Price 80,914.20 Exit Price 81,798.70 BYBIT | Q27: high | S27: 026_2026-05-11_193350_Screenshot_20260511-213326.png | U27: https://discord.com/channels/1042855255089623100/1501271173588193290/1503434974102163536
A28: 27 | B28: 2026-05-12 | C28: 06:19:25 | D28: yes | E28: pnl_share_card | F28: Bybit | G28: 1 | H28: STABLEUSDT | M28: Bybit share card for an open STABLEUSDT 25x long at +144.12% ROI (entry 0.034590, current 0.036652). Posted with 'TP1 @ 0.03737', i.e. he sets the first take-profit target just above the current price. | N28: STABLEUSDT Long 25.0X ROI +144.12% Entry Price 0.034590 Current Price 0.036652 BYBIT | O28: TP1 @ 0.03737 | Q28: high | S28: 027_2026-05-12_061925_Screenshot_20260512-081814.png | U28: https://discord.com/channels/1042855255089623100/1501271173588193290/1503597441675558924
A29: 28 | B29: 2026-05-12 | C29: 06:49:52 | D29: yes | E29: pnl_share_card | F29: Bybit | G29: 1 | H29: STABLEUSDT | M29: Bybit share card of the STABLEUSDT 25x long closed at 0.037370 (entry 0.034590) for +200.92% ROI. Message: he accidentally closed 100% here but says the 0.04 TP is still valid and tells followers to take at least 50% at this level because it is resistance. | N29: STABLEUSDT Long 25.0X ROI +200.92% Entry Price 0.034590 Exit Price 0.037370 BYBIT | O29: I accidentally closed 100% here but 0.04 TP is valid, take at least 50% as this is resistance. @Paladin Notify | Q29: high | S29: 028_2026-05-12_064952_Screenshot_20260512-084847.png | U29: https://discord.com/channels/1042855255089623100/1501271173588193290/1503605103997882428
