Workbook

Sheet Summary
A1: Paladin (ScalpX) — reconstructed trade timeline
A2: Built from all 1,005 messages in #paladin (2026-05-06 to 2026-08-21) plus the 320 screenshots he posted. Blank means he never published the number — nothing here is calculated on his behalf.
A4: The record
A5: Positions catalogued | B5: =COUNTA(Positions!C2:C100000) -> 217
A6: …actually taken by him | B6: =COUNTA(Positions!C2:C100000)-COUNTIF(Positions!E2:E100000,"not_taken")-COUNTIF(Positions!E2:E100000,"never_filled") -> 200
A7: …with a knowable outcome | B7: =COUNTIF(Positions!E2:E100000,"win")+COUNTIF(Positions!E2:E100000,"loss")+COUNTIF(Positions!E2:E100000,"breakeven") -> 165
A8: Wins | B8: =COUNTIF(Positions!E2:E100000,"win") -> 120
A9: Losses | B9: =COUNTIF(Positions!E2:E100000,"loss") -> 35
A10: Breakeven | B10: =COUNTIF(Positions!E2:E100000,"breakeven") -> 10
A11: Never resolved in the channel | B11: =COUNTIF(Positions!E2:E100000,"unknown") -> 35
A12: Called but not taken | B12: =COUNTIF(Positions!E2:E100000,"not_taken")+COUNTIF(Positions!E2:E100000,"never_filled") -> 17
A13: Win rate excluding breakeven | B13: =B8/(B8+B9) -> 0.77419355
A14: Win rate including breakeven | B14: =B8/B7 -> 0.72727273
A15: He publicly claimed 85% (May) and 89% (July).
A17: How trades ended
A18: Closed by hand | B18: =COUNTIF(Positions!F2:F100000,"manual_close") -> 62 | C18: =COUNTIFS(Positions!F2:F100000,"manual_close",Positions!E2:E100000,"win") -> 61 | D18: wins, 0 losses
A19: Reached a published target | B19: =COUNTIF(Positions!F2:F100000,"take_profit") -> 45
A20: Hit a stop | B20: =COUNTIF(Positions!F2:F100000,"stop_loss") -> 35 | C20: every loss came this way
A21: Closed flat | B21: =COUNTIF(Positions!F2:F100000,"breakeven") -> 11
A22: Simply stopped being mentioned | B22: =COUNTIF(Positions!F2:F100000,"unknown") -> 43
A24: Did he publish a plan?
A25: Positions with a published stop | B25: =COUNT(Positions!M2:M100000) -> 187
A26: Positions with a published target | B26: =COUNTA(Positions!N2:N100000) -> 122
A27: Positions with a published DCA level | B27: =COUNTA(Positions!L2:L100000) -> 58
A28: …where that DCA actually filled | B28: =COUNTA(Positions!Q2:Q100000) -> 30
A29: Positions where he moved the stop | B29: =COUNTA(Positions!R2:R100000) -> 46
A30: Positions where he took partials | B30: =COUNTA(Positions!T2:T100000) -> 43
A32: Month by month
A33: Month | B33: Wins | C33: Losses | D33: BE | E33: Win rate excl. BE | F33: What he claimed
A34: 2026-05 | B34: =COUNTIFS(Positions!$B$2:$B$100000,"2026-05*",Positions!$E$2:$E$100000,"win") -> 36 | C34: =COUNTIFS(Positions!$B$2:$B$100000,"2026-05*",Positions!$E$2:$E$100000,"loss") -> 13 | D34: =COUNTIFS(Positions!$B$2:$B$100000,"2026-05*",Positions!$E$2:$E$100000,"breakeven") -> 1 | E34: =IFERROR(B34/(B34+C34),"-") -> 0.73469388 | F34: 60 trades, 51W, 9L, 85%, +159.6%
A35: 2026-06 | B35: =COUNTIFS(Positions!$B$2:$B$100000,"2026-06*",Positions!$E$2:$E$100000,"win") -> 34 | C35: =COUNTIFS(Positions!$B$2:$B$100000,"2026-06*",Positions!$E$2:$E$100000,"loss") -> 11 | D35: =COUNTIFS(Positions!$B$2:$B$100000,"2026-06*",Positions!$E$2:$E$100000,"breakeven") -> 4 | E35: =IFERROR(B35/(B35+C35),"-") -> 0.75555556 | F35: no summary ever posted
A36: 2026-07 | B36: =COUNTIFS(Positions!$B$2:$B$100000,"2026-07*",Positions!$E$2:$E$100000,"win") -> 31 | C36: =COUNTIFS(Positions!$B$2:$B$100000,"2026-07*",Positions!$E$2:$E$100000,"loss") -> 7 | D36: =COUNTIFS(Positions!$B$2:$B$100000,"2026-07*",Positions!$E$2:$E$100000,"breakeven") -> 3 | E36: =IFERROR(B36/(B36+C36),"-") -> 0.81578947 | F36: 45 trades, 40W, 5 SLs, 89%, +23.5R
A37: 2026-08 | B37: =COUNTIFS(Positions!$B$2:$B$100000,"2026-08*",Positions!$E$2:$E$100000,"win") -> 19 | C37: =COUNTIFS(Positions!$B$2:$B$100000,"2026-08*",Positions!$E$2:$E$100000,"loss") -> 4 | D37: =COUNTIFS(Positions!$B$2:$B$100000,"2026-08*",Positions!$E$2:$E$100000,"breakeven") -> 2 | E37: =IFERROR(B37/(B37+C37),"-") -> 0.82608696 | F37: log ends 21 Aug
A40: The sheets
A41: Positions — one row per trade, from the call to the exit. The "planned" columns are what he published up front; the "avg entry / partials / exit" columns are what the messages and screenshots show he actually did.
A42: Events — all 1,242 individual actions (calls, entries, DCAs, stop moves, partials, exits) with his exact words and a link to the message.
A43: What he watches — the signals, risk rules, entry patterns and management tactics the record supports, each with his own quotes.
A44: His scoreboard — every performance claim he made, so his numbers can be checked against the Positions sheet.
A45: A "medium" or "low" confidence on a position means part of it was inferred; the Trust notes column says which part.

Sheet Positions
A1: # | B1: First seen | C1: Symbol | D1: Side | E1: Outcome | F1: Exit type | G1: R | H1: Card ROI % | I1: Leverage | J1: Planned entry | K1: Entry note | L1: Planned DCA | M1: Planned stop | N1: Planned targets | O1: Risk note | P1: Avg entry | Q1: DCA filled | R1: Stop moves | S1: Target changes | T1: Partials taken | U1: Exit price | V1: Entry time | W1: Exit time | X1: Held (h) | Y1: Thesis | Z1: What he did | AA1: Indicators | AB1: Market context | AC1: Still open | AD1: Confidence | AE1: Trust notes | AF1: Messages | AG1: First message link
A2: 1 | B2: 2026-05-07 02:34:43 | C2: UNIUSDT | D2: long | E2: win | F2: take_profit | G2: 1.4 | H2: 101.21 | I2: 50 | J2: 3.46 | K2: 3.46 CMP | M2: 3.28 | N2: 3.669 | P2: 3.458 | R2: 3.46 (to_entry) | S2: 3.7/4 | T2: 50% at 3.528 | U2: 3.7 | V2: 2026-05-07 02:34:43 | W2: 2026-05-08 19:41:13 | X2: 41.1 | Y2: Simple long on UNI at market with a first target at 3.669; he took it as a clean setup and later treated it as the channel's first win. | Z2: He called the long at 3.46 CMP with a single 3.669 target and a 3.28 stop, noting he takes TPs manually but followers could set the order. A day and a half later, 0.7R up, he closed 50% and framed it as the channel's first win, lifted his own target to 3.7 (telling followers they could hold for 4) and moved the stop to breakeven at 3.46. An hour later UNI 'blew up' and he took the remainder at 3.7 for around 1.4R. The next morning he re-posted the closed 50x card (entry 3.458, exit 3.528, +101.21%) inside a batch update and said he expected UNI to see $4 by the coming weekend. | AD2: high | AE2: The card re-posted in msg 36 shows exit 3.528, not the 3.7 he announced in text - it documents the 50% partial (its +101.21% matches the ROI attached to that partial), so the partial price is carried from that card. No explicit fill price beyond '@ 3.7' was given for the second half. | AF2: #5, #26, #29, #36 | AG2: https://discord.com/channels/1042855255089623100/1501271173588193290/1501728955470712946
A3: 2 | B3: 2026-05-07 02:35:46 | C3: ETHUSDT | D3: long | E3: loss | F3: stop_loss | J3: 2348 | K3: 2348 CMP; said he takes TP manually so he might close before or after 2420 | M3: 2292 | N3: 2420 | V3: 2026-05-07 02:35:46 | W3: 2026-05-07 19:48:16 | X3: 17.2 | Y3: Plain market long on ETH targeting 2420, with the intention of taking profit manually rather than at a fixed limit. | Z3: He called the long at 2348 CMP with a 2292 stop and a 2420 target, saying he would close manually. The trade first travelled far enough that he describes it as having 'gone BE', then an unexpected drop on 7 May took it out along with his BTC long. He never posted a fill price for the stop-out, only that ETH stopped. He apologised for a rough start to the run. | AB3: unexpected drop; BTC was about to be stopped at the same time | AD3: medium | AE3: No exit price posted, so exit_price is null; the stated stop was 2292. His wording 'Both went BE but didn't expect a drop so stopped' leaves it ambiguous whether he was taken out at the original 2292 stop or at a breakeven stop he had moved up - he treats it as a loss and apologises, so it is recorded as a loss. | AF3: #6, #15 | AG3: https://discord.com/channels/1042855255089623100/1501271173588193290/1501729216969048065
A4: 3 | B4: 2026-05-07 11:06:57 | C4: BTCUSDT | D4: long | E4: loss | F4: stop_loss | J4: 81500 | K4: 50% of size at 81.5k, 50% held back for the 80.8k DCA (msg 9) | L4: 80800 | M4: 79600 | N4: 82500 | O4: Scalp. If he did not update, followers were to trim 20-25% at the first TP (82.5k) | Q4: 80900 (filled manually at 80.9k because price missed his 80.8k limit by about $10) | V4: 2026-05-07 11:06:57 | W4: 2026-05-07 19:48:16 | X4: 8.7 | Y4: A scalp long into the 80k region: he thought BTC could retrace further but expected the 80s to hold and at least a visit to 82k+, which would give a scalp. | Z4: He called the scalp at 81.5k with half the size and the other half saved for a DCA at 80.8k (msgs 8-9), and when price missed that limit by about $10 he filled the second half manually at 80.9k (msg 10). He never posted an average or a card for it. That evening BTC dropped unexpectedly and it was stopped: 'ETH stopped, BTC about to get stopped (on some exchanges maybe it already did). Both went BE but didn't expect a drop so stopped' (msg 15). Followers had been told to trim 20-25% at 82.5k if he went quiet, but price never reached the first target. | AA4: support/resistance | AB4: BTC weak and possibly retracing further; he was already carrying UNI and ETH longs he called risky for the same reason (msg 7). | AD4: medium | AE4: No exit price was ever posted - 79.6k is his published stop, not a confirmed fill, and msg 15 says it was still in the process of being stopped across exchanges. Average entry not stated (50% at 81.5k, 50% at 80.9k), so it is left null rather than blended. 'Both went BE' is ambiguous: if he had moved the stop to breakeven this would be a scratch rather than a loss, but the event is logged as a stop-out so it is recorded as a loss. | AF4: #8, #9, #10, #15 | AG4: https://discord.com/channels/1042855255089623100/1501271173588193290/1501857862148952084
A5: 4 | B5: 2026-05-07 15:32:55 | C5: ZROUSDT | D5: long | E5: win | F5: breakeven | H5: 178.94 | I5: 50 | J5: 1.48 | K5: 1.48 CMP; three minutes later he corrected that CMP was really 1.486 because price moved fast. He advised followers to keep 50-30% back for a DCA but said he was not saving for DCA himself | L5: 1.45 | M5: 1.36 | N5: 1.5523 | O5: Keep 50-30% funds for DCA but optional you can go all in here I'm not saving for DCA personally | P5: 1.4744 | S5: 1.55 | T5: 25% at 1.53 | U5: 1.4744 | V5: 2026-05-07 15:32:55 | W5: 2026-05-11 00:40:45 | X5: 81.1 | Y5: A straight CMP long on ZRO managed by hand, with 1.5523 as the fallback target if he went quiet. He flagged it as the last new position he would open before one of his others exited. | Z5: He called the long at 1.48 CMP and corrected the fill to 1.486 three minutes later after a fast move, advising followers to split 50/50 with a DCA at 1.45 while he took his own size in one go. By the 9 May batch update his 50x card was open at +34.43% (entry 1.4744, mark 1.4849). On 10 May he complained that ZRO had been rejecting from the 1.5523 target for three days and told the room to take profit early on any drop; ninety minutes later he booked 25% at 1.53 for +178.94% and said he would fully exit around 1.55+. The rest was stopped at breakeven just after midnight, straight after TP1 - and in the same message he re-entered the same long. | AD5: high | AE5: His card entry (1.4744) is below both the 1.48 call and the 1.486 corrected CMP, so part of the size filled lower than either quoted price and he never explained it. No exit fill is quoted anywhere: 1.4744 is used because that is his stated entry and a breakeven stop exits there. Msg 57 both closes this position and opens the next ZRO long. | AF5: #11, #12, #13, #36, #53, #54, #57 | AG5: https://discord.com/channels/1042855255089623100/1501271173588193290/1501924796072464426
A6: 5 | B6: 2026-05-07 15:41:53 | C6: GOLD | D6: long | E6: not_taken | F6: not_taken | O6: Declined the setup because he already had too many positions open. | Y6: Gold looked longable to him, but position capacity - not the chart - kept him out. | Z6: He flagged gold as longable and immediately declined it: 'Gold looks Longable but too many positions for now!' No entry, stop or target was published and he never came back to this particular idea; gold does not appear again until a 3R trade he mentions on 28 May. | AD6: high | AE6: An idea floated and dropped in one message - no levels of any kind, so nothing to link a later gold trade to. | AF6: #14 | AG6: https://discord.com/channels/1042855255089623100/1501271173588193290/1501927050284372139
A7: 6 | B7: 2026-05-08 01:40:42 | C7: BTCUSDT | D7: long | E7: win | F7: manual_close | H7: 72.31 | I7: 100 | J7: 79700 | K7: 79.7k CMP | L7: 79469, 78600 | M7: 78500 | N7: 80500 | O7: Soft stop was a 1h close under 79k, hard stop 78.5k; DCAs were equal-sized to the initial entry | P7: 79764.4 | Q7: 79469 (equal-sized DCA filled, blended entry 79590 (breakeven)) | R7: 77600 (widen) | S7: 81000/82000 | T7: 50% at 79590 | U7: 80341.2 | V7: 2026-05-08 01:40:42 | W7: 2026-05-09 06:06:56 | X7: 28.4 | Y7: Long from 79.7k CMP with a conditional invalidation (1h close under 79k) for a push to 80.5k, then held into what he believed would be a hard weekend pump toward the previous daily high. | Z7: He called it at 79.7k CMP with a soft stop (1h close under 79k) and a hard stop at 78.5k (msg 17). With the trade at breakeven he added an equal-sized DCA at 79469 (msg 18), which filled and left the blend at 79590 (msg 19). He then told everyone to take that DCA half back off at breakeven and re-place it as a limit at 78.6k (msgs 19, 21) and widened the stop to 77.6k to sit under the new level - 'I know it's sound messy but I'm confident we will exit this one in green' - and the second DCA never filled. He posted a screenshot showing his own entry at 79,564.80 and offered an optional 20% trim at 80.5k (msg 25), then said he was looking to close in the 81-82k area on a 4h close above 80.5k (msg 33). He closed it manually the next morning at 80.4k - card 79,764.40 to 80,341.20, +72.31% on 100x (msgs 36, 40) - and afterwards clarified that 79.5k was the original entry and it only shows as 79.7k because he added margin (msg 41). | AA7: 1h close, 4h close, previous daily high | AB7: Straight after the previous day's stop-out; he expected a hard weekend pump, with a 4h close above 80.5k opening 81-82k. | AD7: high | AE7: Four entry figures appear for the same trade: 79,590 blended after the DCA (msg 19), 79,564.80 on the 05-08 screenshot (msg 25), 79.5k which he calls the original entry (msgs 33, 41), and 79,764.40 on the closing card, which he explains by having added margin; avg_entry uses the closing card. Both DCA levels were added after the call, not published with it. After closing he twice talked about re-longing (CMP with SL 79k or waiting for ~80.3k in msg 42, then a 79k entry / 78k DCA / 77k SL setup in msg 43 with explicit instructions not to leave limits) but never took either - the next BTC trade was a short on 05-11. | AF7: #17, #18, #19, #21, #25, #33, #36, #40, #41 | AG7: https://discord.com/channels/1042855255089623100/1501271173588193290/1502077749882523759
A8: 7 | B8: 2026-05-08 06:43:06 | C8: AVNTUSDT | D8: long | E8: win | F8: unknown | H8: 246.69 | I8: 50 | J8: 0.158 | K8: 0.158 CMP | M8: 0.1411 | N8: 0.1746, 0.2023 | P8: 0.15851 | S8: 0.1746 | T8: 0.16709 | V8: 2026-05-08 06:43:06 | Y8: No reasoning was published beyond the levels: a plain CMP long on AVNT with a two-step ladder at 0.1746 and 0.2023 and a stop at 0.1411. | Z8: He called it at 0.158 CMP with a 0.1411 stop and targets at 0.1746 and 0.2023. By the 9 May batch update the 50x card was open at +265.55% (entry 0.15851, mark 0.16787) and he told the room to take profit whenever they liked rather than let winners round-trip. On the evening of 10 May he announced TP1 at 0.16709, the card still open at +246.69%, and pulled the plan in - the rest would now come off at 0.1746 instead of running to 0.2023. That final exit is never reported: AVNT does not appear in the log again. | AC8: yes | AD8: medium | AE8: Profit was definitely banked at TP1, which is why this is scored a win, but the size of that partial and the fate of the remainder are both unknown - the position simply drops out of the log after 10 May. Marked still open only because nothing reports it closing. | AF8: #22, #36, #52 | AG8: https://discord.com/channels/1042855255089623100/1501271173588193290/1502153850231193630
A9: 8 | B9: 2026-05-08 18:47:55 | C9: KERNELUSDT | D9: long | E9: win | F9: unknown | H9: 49.35 | I9: 20 | J9: 0.064 | K9: 0.064, confirmed as CMP twelve seconds later | M9: 0.581 | N9: 0.066 | O9: High win rate, low R trade; stop is a 4h close under the level or the hard stop | P9: 0.06454 | R9: None (to_entry) | S9: 0.0673 | T9: 0.06615 | V9: 2026-05-08 18:47:55 | Y9: Explicitly a high win rate, low R trade - a 0.064 CMP long targeting about 0.066 first, managed by hand with a 4h close as the soft stop. | Z9: He called KERNEL at 0.064 CMP as a high win rate / low R trade, with the stop written as a 4h close under 0.59 or a hard stop at 0.581 - both an order of magnitude away from the entry. Ten hours later he announced TP1 at 0.06615 with the 20x card at +49.35% and set the next target at 0.0673. The same card reappeared in his 4:48 batch update, still open, with the room told to take profit whenever they liked. Nine minutes after that he posted the reminder to move the stop to entry after TP1, replying to the KERNEL message. Nothing more about KERNEL is ever posted, so the final exit is unknown. | AA9: 4h close | AC9: yes | AD9: medium | AE9: The published stops (4h close under 0.59, hard stop 0.581) are almost certainly typos for 0.059 / 0.0581 against a 0.064 entry - recorded exactly as posted. The stop-to-entry move is inferred from reply context and carries no level. TP1 was announced but the card still showed the position open and no exit is ever reported, so the win rests on the announced TP1 alone. | AF9: #27, #28, #35, #36, #39 | AG9: https://discord.com/channels/1042855255089623100/1501271173588193290/1502336255449366558
A10: 9 | B10: 2026-05-08 19:49:28 | C10: SNXUSDT | D10: long | E10: win | F10: manual_close | H10: 55.8 | I10: 25 | J10: 0.354 | K10: 0.354 CMP for half the size, the other half reserved for a 0.334 DCA | L10: 0.334 | M10: 0.31 | N10: 0.39 | O10: DCA is 50% of size; TP1 at 0.39 is 1R and closes 50% of the position, TP2 to be given later. | P10: 0.3545 | U10: 0.3626 | V10: 2026-05-08 19:49:28 | W10: 2026-05-10 23:33:31 | X10: 51.7 | Y10: Long SNX at market with a laddered plan - half now, half at 0.334 - and a first target at 0.39 that he defined as 1R. | Z10: He called SNX long at 0.354 CMP with a 0.334 DCA for the second half, TP1 0.39 (1R, 50%) and a 0.31 stop. The DCA never came - SNX went straight up and by the next morning his 25x card was +118.67% (entry 0.3545, mark 0.3727), which he showed in a batch update telling members to take TP whenever they wanted rather than let trades round-trip. Two days later he posted that he was 'this close to closing SNX idk why but I just want to close', and that evening he closed the whole thing at 0.3626 for +55.80%, saying he expected a pullback and would re-open after Monday. | AB10: Expected a broad market pullback at the time he closed. | AD10: high | AE10: Closed on gut feel well short of the 0.39 target; the position had been +118.67% on the card 40 hours before he exited at +55.80%, so he gave back a good part of the move. He never re-opened SNX after Monday in this log. | AF10: #31, #36, #53, #56 | AG10: https://discord.com/channels/1042855255089623100/1501271173588193290/1502351744259063878
A11: 10 | B11: 2026-05-09 04:52:10 | C11: SYRUPUSDT | D11: long | E11: win | F11: manual_close | H11: 67.61 | I11: 25 | P11: 0.25328 | U11: 0.26013 | W11: 2026-05-09 04:52:10 | Y11: A leftover trade from his Journals that he had held for ten days; he still believed it would blow up but closed it out of impatience. | Z11: Only the exit of this trade falls inside the log. The share card shows a 25x long from 0.25328 closed at 0.26013 for +67.61%. He says he had been holding it for about ten days and was closing purely because it was getting annoying, adding that he was sure it would blow up right after he was out. Nothing about the original entry, stop or targets was ever posted here. | AD11: medium | AE11: Entry, stop and targets are unknown - the position was opened in his 'Journals' before this log begins, so entry_time and duration cannot be given. His '10 days' remark puts the entry around 2026-04-29 but he never states a date. | AF11: #38 | AG11: https://discord.com/channels/1042855255089623100/1501271173588193290/1502488322143162518
A12: 11 | B12: 2026-05-09 11:51:05 | C12: STABLEUSDT | D12: long | E12: win | F12: take_profit | H12: 231.02 | I12: 25 | J12: 0.0346 | K12: 0.0346 CMP, flagged as a swing that would take time | M12: 0.03 | N12: 0.04 | P12: 0.03459 | S12: 0.03737 | T12: 100% at 0.03737 | U12: 0.04 | V12: 2026-05-09 11:51:05 | W12: 2026-05-13 06:13:16 | X12: 90.4 | Y12: Swing long on a slow-moving shitcoin from 0.0346 up to the 0.04 round number, explicitly not for scalpers. | Z12: He called STABLE as a swing at 0.0346 CMP with a 0.04 target and a 0.03 stop, warning it would take time - and for three days it did nothing ('STABLE has been really STABLE'). On 12 May he added a first target at 0.03737 with the position +144% at 25x, then accidentally closed 100% of it right at that level for +200.92%, telling followers the 0.04 target was still valid but to take at least 50% there because it is resistance. Screenshots hours later showed he still had a live copy of the same long on MEXC (entry 0.03453, +248%), so he was not actually flat. On 13 May the full 0.04 target printed - a 20% unleveraged move, +231.02% ROI at 20x. | AA12: resistance | AB12: quiet tape; he pointed intraday traders at his BTC scalp instead | AD12: medium | AE12: Same idea run on two exchanges: entry 0.03459 at 25x on the first (closed by accident at 0.03737) and 0.03453 at 20x on MEXC (held to the 0.04 target). Treated as one position. avg_entry/leverage use the first card; the final exit price 0.04 is his stated target level, which he says was hit in full rather than a posted fill. | AF12: #44, #51, #82, #83, #84, #86, #89 | AG12: https://discord.com/channels/1042855255089623100/1501271173588193290/1502593742513635530
A13: 12 | B13: 2026-05-09 13:58:20 | C13: ETHUSDT | D13: long | E13: win | F13: manual_close | H13: 124.58 | I13: 100 | J13: 2310 | K13: 2310 CMP with 50% of size held back for the 2290 DCA | L13: 2290 | M13: 2260 | N13: 2350 | O13: DCA is 50% of size | P13: 2311.73 | S13: 2350 | U13: 2340.53 | V13: 2026-05-09 13:58:20 | W13: 2026-05-10 18:45:44 | X13: 28.8 | Y13: Weekend scalp long on ETH from 2310 CMP with a 50% DCA underneath at 2290. | Z13: He called the long at 2310 CMP with a 2290 DCA and a 2260 stop, and two minutes later put the target at 2350+, saying he would close manually. The position sat through the weekend and on 10 May he closed all of it at 2340.53 from an average of 2311.73 - +124.58% at 100x - calling it good enough for a weekend scalp. Two minutes after the screenshot went out, 2350 traded, so the target he had given was reached anyway. He never used the 2290 DCA. | AB13: weekend session | AD13: high | AE13: The original call carried no target; the 2350 level came two minutes later in MSG 46 and is recorded as the planned take profit. | AF13: #45, #46, #49, #50 | AG13: https://discord.com/channels/1042855255089623100/1501271173588193290/1502625769904406701
A14: 13 | B14: 2026-05-09 14:12:56 | C14: TAKEUSDT | D14: long | E14: not_taken | F14: not_taken | O14: Wanted at least 2 open positions closed before adding new ones. | Y14: TAKE looked good for a long but he was at his self-imposed position limit. | Z14: He posted that TAKE looked good for a long but that too many positions were already running - he wanted at least two closed before opening anything new - and signed off with 'see you at TPs'. No levels were given and TAKE is never mentioned again. | AD14: high | AE14: Pure pass; no entry, stop or target published. | AF14: #48 | AG14: https://discord.com/channels/1042855255089623100/1501271173588193290/1502629441908510731
A15: 14 | B15: 2026-05-11 00:40:45 | C15: ZROUSDT | D15: long | E15: win | F15: take_profit | H15: 215.72 | I15: 50 | J15: 1.486 | K15: re-entered at 1.486 in the same message that reported the previous ZRO position stopping at breakeven | L15: 1.42 | M15: 1.37 | N15: 1.55 | P15: 1.4772 | T15: 20% at 1.5369 | U15: 1.5457 | V15: 2026-05-11 00:40:45 | W15: 2026-05-11 12:32:58 | X15: 11.9 | Y15: An immediate re-entry of the same ZRO long seconds after the first one was stopped at breakeven - same idea and same 1.55 target, with a lower stop and a DCA at 1.42. | Z15: He announced the breakeven stop and the re-entry in the same message at 00:40 on 11 May: long again at 1.486, DCA 1.42, TP1 1.55, SL 1.37 - his card shows the fill at 1.4772. At 09:12 he booked 20% at 1.5369 for +189.93% and made a point of not moving the stop to entry, leaving the original 1.37 in place. Three hours later the 1.55 target filled: the card shows 1.5457 and +215.72%. He noted straight after that this was the second time he had milked the same setup. | AD15: high | AE15: He explicitly refused to move the stop to entry after the 20% partial, so the original 1.37 stood to the end. The 1.42 DCA is never reported as filling. | AF15: #57, #67, #72, #73 | AG15: https://discord.com/channels/1042855255089623100/1501271173588193290/1503149825196036228
A16: 15 | B16: 2026-05-11 02:30:48 | C16: BTCUSDT | D16: short | E16: win | F16: manual_close | H16: 109.47 | I16: 100 | J16: 82300 | K16: 82.3k CMP | L16: 83000 | M16: 83650 | N16: 80000, 81000 | P16: 82202.8 | U16: 81302.9 | V16: 2026-05-11 02:30:48 | W16: 2026-05-11 03:58:37 | X16: 1.5 | Y16: A counter-trend scalp short into the 82.3k spike, looking to cover in the 80-81k region. | Z16: He shorted at 82.3k CMP with a DCA planned higher at 83k and a stop at 83,650 (msg 59), then said he was looking to scalp it around 80-81k (msg 60). BTC sold off immediately so the 83k DCA never came into play, and he covered 88 minutes later at 81,302.90 from 82,202.80 for +109.47% on 100x - 'TPed, fast top short, closed' (msg 61). He banked it above his own 80-81k target zone rather than waiting for it, and immediately said he would flip long once price stabilised around 80k (msg 62). | AB16: He was openly bullish for the week, expecting 84-85k (msg 58), and took this quick top short against his own bias. | AD16: high | AE16: He calls it a TP, but the fill at 81,302.90 is above the 80-81k target zone, so it is recorded as a manual close in profit rather than a take-profit. | AF16: #59, #60, #61 | AG16: https://discord.com/channels/1042855255089623100/1501271173588193290/1503177518499233970
A17: 16 | B17: 2026-05-11 09:13:29 | C17: BTCUSDT | D17: long | E17: win | F17: manual_close | H17: 109.31 | I17: 100 | J17: 80900 | K17: 80.9k CMP in the public call; he had already started scaling in from 80.6k before publishing it (msg 68). No DCA on this one. | M17: 79500 | N17: 81500, 81600 | O17: He kept the wider 79.5k stop, 'playing safe here, scalp'; a tighter optional stop at 79,750 was offered to followers (msg 71) | P17: 80914.2 | S17: 81500/81600 | U17: 81798.7 | V17: 2026-05-11 09:13:29 | W17: 2026-05-11 19:32:08 | X17: 10.3 | Y17: Long the 80k region on the view that if the 80s hold, BTC runs to 84k - traded as a scalp he intended to close manually around 81.5-81.6k. | Z17: He said he would long once BTC stabilised, with the 80k region as the place he wanted (msg 62), then started scaling in privately from 80.6k with a 79.5k stop and posted the running 150x card at +51.78% (msg 68). Once confident he published the formal call at 80.9k CMP with no DCA and the same 79.5k stop (msg 70), offering followers a tighter 79,750 stop while keeping the wider one himself (msg 71). Mid-afternoon he said he would close manually targeting 81.5-81.6k (msg 74). He closed the whole position that evening (msg 75) and posted the proof card: entry 80,914.20, exit 81,798.70, +109.31% on 100x (msg 76) - above his own stated target. | AA17: support/resistance | AB17: Right after covering the top short; he wanted price to stabilise before longing, and read 80k holding as the trigger for a run to 84k. | AD17: high | AE17: One position run on more than one account: the entry card (msg 68) is 150x and the closing card (msg 76) is 100x. Leverage and ROI record the closing card. The 80.6k private scale-in and the 80.9k published entry are the same trade, not two. | AF17: #62, #68, #69, #70, #71, #74, #75, #76 | AG17: https://discord.com/channels/1042855255089623100/1501271173588193290/1503199754027270164
A18: 17 | B18: 2026-05-12 04:30:58 | C18: BTCUSDT | D18: long | E18: loss | F18: stop_loss | J18: 81300 | K18: Half at 81.3k, half at the 80.7k DCA; he flagged it as slightly risky so followers could go half risk or simply enter at the DCA | L18: 80700 | M18: 79500 | O18: Slightly risky - half risk or DCA-only entry suggested for followers | P18: 81000 | Q18: 80700 (DCA leg filled 20 minutes after the call, blended average 81k and already in profit) | S18: 82000 -> 82000 | V18: 2026-05-12 04:30:58 | W18: 2026-05-13 18:15:09 | X18: 37.7 | Y18: Another BTC scalp long, from 81.3k with a DCA at 80.7k, wanting a 4h close above 81.1k to open a run to 82k. | Z18: He called it at 81.3k with a DCA at 80.7k and a 79.5k stop, telling followers it was slightly risky so they could halve risk or just enter at the DCA (msg 79). The DCA filled 20 minutes later at a perfect level - 'if you entered at DCA you sniped' - taking his average to 81k in profit (msgs 80-81). By the next morning it was back around breakeven (msg 90); he said he needed a 4h close above 81.1k to get 82k, then set the official TP at 82k while flagging that he would probably exit early at 81.5-81.6k (msg 98). Price missed that trim level by about $150 and reversed into his stop: 'Sorry guys lost on BTC, stayed above profits for a long time but didn't TP, wanted to trim first @ 81.5k but missed by 150$' (msg 99). He re-entered a new long a minute later. | AA18: 4h close | AB18: Continuation of his bullish 84-85k week view after two profitable BTC scalps. | AD18: high | AE18: The loss is stated plainly but no exit price or card was posted - 79.5k is his published stop, not a confirmed fill. Average entry 81k is his own figure. The call carried no TP; the 82k target only appeared on 05-13. | AF18: #79, #80, #81, #90, #98, #99 | AG18: https://discord.com/channels/1042855255089623100/1501271173588193290/1503570149297360977
A19: 18 | B19: 2026-05-12 15:01:26 | C19: XRPUSDT | D19: long | E19: win | F19: manual_close | H19: 23.45 | I19: 100 | J19: 1.448 | K19: 1.448 CMP | M19: 1.4 | N19: 1.5, 1.525 | P19: 1.4497 | U19: 1.4531 | V19: 2026-05-12 15:01:26 | W19: 2026-05-14 17:30:30 | X19: 50.5 | Y19: Long XRP at market with targets at 1.5 and 1.525 and a 1.4 stop; no reasoning was given with the call. | Z19: He called the long at 1.448 CMP with two targets and a 1.4 stop. It went nowhere for two days and sat around breakeven, and on 14 May price nearly touched his stop, which he read as the setup being invalidated - so he closed at 1.4531 from 1.4497 for a token +23.45% at 100x rather than risk the full stop. Minutes later it broke out, and by that evening it had run to 1.5431, through both of his targets. He posted the chart himself and called it a fumble, saying the idea was right even though he had exited early. | AB19: not stated | AD19: high | AE19: Closed for a tiny profit, so it counts as a win, but he treats it as a fumbled trade because the full target hit after he was out. | AF19: #85, #90, #108, #110, #124 | AG19: https://discord.com/channels/1042855255089623100/1501271173588193290/1503728811768811663
A20: 19 | B20: 2026-05-13 06:41:20 | C20: ETHUSDT | D20: long | E20: unknown | F20: unknown | J20: 2293 | K20: 2293 CMP; the message went out late and he confirmed the entry was still good at 2298 | M20: 2245 | N20: 2336 | O20: Risky trade go half | S20: 2336 | V20: 2026-05-13 06:41:20 | Y20: Risky market long on ETH with a 2245 stop, taken at half size - 'I hate ETH'. | Z20: He called the long at 2293 CMP with a 2245 stop, flagged it as risky and told people to go half size. Eleven seconds later he noted the message had gone out late and that 2298 was still a valid entry. Forty minutes after that he gave the first target, 2336, joking that he would take a break if ETH broke his streak. Nothing in the log ever says how this one ended. | AB20: not stated | AD20: low | AE20: No exit, stop-out or update of any kind after MSG 95. He floats a fresh ETH long idea on 16 May, so this one had presumably been closed or stopped by then, but nothing states it - outcome left unknown. | AF20: #91, #92, #95 | AG20: https://discord.com/channels/1042855255089623100/1501271173588193290/1503965346304884828
A21: 20 | B21: 2026-05-13 06:52:43 | C21: SOLUSDT | D21: long | E21: win | F21: manual_close | H21: 17.79 | I21: 100 | J21: 95.5 | K21: 95.5 CMP | M21: 93.5 | N21: 97 | P21: 95.53 | U21: 95.7 | V21: 2026-05-13 07:02:05 | W21: 2026-05-13 12:11:15 | X21: 5.2 | Y21: He thought SOL was a much better long from CMP than the ETH trade he had already called, so he offered SOL as an optional add-on long. | Z21: Ten minutes after saying SOL looked a lot better to long than the ETH he had already called, he posted the SOL long at 95.5 CMP with TP 97 and SL 93.5, framed as optional ('if anyone's looking long for SOL'). Five hours later he closed it himself at 95.7 for a token +17.79% on 100x, explicitly to stay on the safe side and protect his streak while his other three longs ran. Twenty seconds after that he told risk-tolerant members the setup was still valid and they could keep it running rather than close with him. | AD21: high | AE21: He exited early for streak-protection reasons rather than at the 97 target; the follower guidance (keep it running) differs from his own action and is recorded in the story only. | AF21: #93, #94, #96, #97 | AG21: https://discord.com/channels/1042855255089623100/1501271173588193290/1503968208800190536
A22: 21 | B22: 2026-05-13 18:16:30 | C22: BTCUSDT | D22: long | E22: win | F22: manual_close | H22: 202.99 | I22: 100 | J22: 79400 | K22: CMP entry (msg 101) with about 25% of size held back for the DCA | L22: 79000 | M22: 77900 | N22: 82000 | O22: Save some for DCA - around 25%, half of what you're putting on now | P22: 79284.35 | Q22: 79000 (25% DCA filled - confirmed when he posted the 79.2k average running in heavy profit; the actual fill time was never stated) | U22: 80893.8 | V22: 2026-05-13 18:16:30 | W22: 2026-05-14 18:02:51 | X22: 23.8 | Y22: Immediate re-entry after the stop-out: long 79.4k CMP with 25% kept back for a 79k DCA, targeting 82k, on his scripted path of a dip to 78.5k, a bounce and a news-driven push to 81-82k. | Z22: He called the re-entry within a minute of announcing the previous loss - long 79.4k CMP, 25% saved for a DCA (msgs 100-101) - and gave the DCA level as 79k two minutes later (msg 102). The DCA filled and by the following afternoon he showed the position at an average of 79.2k running in heavy profit (msg 108), with a card at 79,284.35 and +108.28% on 100x (msg 109), noting BTC was moving exactly as he had mapped it (msg 111). He closed the whole position at about 81k for +202.99% on 100x - card 79,284.35 to 80,893.80 - saying it made back the losses from both earlier stop-outs (msg 112). He then posted the same trade from two other accounts: BloFin 30x, 79,313.40 to 80,926.40, +61% (msg 115), and a 250x card at +448.51% (msg 116). | AA22: news | AB22: Clarity-act headlines were the catalyst; he had publicly scripted the move - dip to 78.5k, bounce, news, 81-82k (msgs 111, 121). | AD22: high | AE22: One position run on at least three accounts (100x main, BloFin 30x, 250x) - the three cards are not three trades. He exited at ~81k, below his published 82k target. Stated average 79.2k vs 79,284.35 on the card; the BloFin card shows 79,313.40. | AF22: #100, #101, #102, #108, #109, #111, #112, #115, #116 | AG22: https://discord.com/channels/1042855255089623100/1501271173588193290/1504140287096651806
A23: 22 | B23: 2026-05-14 03:17:11 | C23: SOLUSDT | D23: long | E23: win | F23: manual_close | H23: 45.03 | I23: 100 | J23: 91.25 | K23: 91.25 CMP | M23: 87.5 | O23: Soft stop was a 4h close under 88, with a hard stop at 87.5. | P23: 91.05 | R23: None (tightened_unspecified) | U23: 91.46 | V23: 2026-05-14 03:17:11 | W23: 2026-05-14 17:30:30 | X23: 14.2 | Y23: A second SOL long at market the morning after the first one, with the stop defined on a 4h close under 88 rather than a hard level. | Z23: He longed SOL again at 91.25 CMP, publishing no target and a two-part stop: a 4h close under 88, or a hard 87.5. Thirty-six minutes later he said he had modified the SOL stop because the trade was already in profit, but never gave the new level. That afternoon he closed SOL together with XRP 'in minor profits' - his card shows entry 91.05, close 91.46, +45.03% on 100x. | AA23: 4h close | AD23: high | AE23: The stop move at msg 106 has no level attached - he only said it was modified and that members could adjust too, so 'to' is null. | AF23: #103, #106, #108 | AG23: https://discord.com/channels/1042855255089623100/1501271173588193290/1504276354516910202
A24: 23 | B24: 2026-05-14 03:18:10 | C24: BBUSDT | D24: long | E24: win | F24: manual_close | H24: 116.46 | I24: 25 | J24: 0.03535 | K24: 0.03535 CMP, risky half-margin trade | M24: 0.3 | N24: 0.39, 0.41 | O24: Flagged risky - half margin. | P24: 0.03538 | S24: 0.404 | U24: 0.0371 | V24: 2026-05-14 03:18:10 | W24: 2026-05-15 03:20:30 | X24: 24 | Y24: A deliberately risky, half-margin long on BB taken at market a minute after the SOL long. | Z24: He called BB long at 0.03535 CMP as a risky half-margin trade, posting TP 0.39-0.41 and SL 0.3. Thirty-five minutes later he dropped the first target - 'Remove the first TP 0.039 will take full TP around 0.404' - so his own plan became a single full exit. A day later he admitted he had 'totally forgot about this one' and closed early at 0.0371 for +116.46% on 25x rather than waiting for the target. | AD24: medium | AE24: Levels recorded exactly as posted, but the decimals are almost certainly wrong: with a 0.03535 entry the TP 0.39-0.41 and SL 0.3 should read 0.039-0.041 and 0.03 - his own follow-up message calls the first target '0.039' while the revised full TP is written '0.404'. The exit at 0.0371 sits between the plausible 0.039 target and the entry, consistent with the dropped-decimal reading. | AF24: #104, #105, #127 | AG24: https://discord.com/channels/1042855255089623100/1501271173588193290/1504276604292042863
A25: 24 | B25: 2026-05-14 10:40:51 | C25: ENSUSDT | D25: long | E25: win | F25: manual_close | H25: 161.15 | I25: 50 | J25: 6.89 | K25: 6.89 CMP | M25: 6.3 | N25: 7.69 | P25: 6.9 | T25: 50% at 7.171 | U25: 7.135 | V25: 2026-05-14 10:40:51 | W25: 2026-05-14 19:19:52 | X25: 8.7 | Y25: Long ENS at market towards 7.69, with a soft stop defined as a 1h close under 6.3 rather than a hard level. | Z25: He called ENS long at 6.89 CMP with the stop set as a 1h close under 6.3 and a 7.69 target. By late afternoon it was +141.91% at 50x from 6.900 and he was holding for 'fat profits'. At 7.171 he took 50% off (+190.71%) and told followers they could close the whole thing there. An hour later he was completely out at 7.135 for +161.15%, well short of the 7.69 target. | AA25: 1h close | AB25: not stated | AD25: high | AE25: The 6.3 stop was a 1h-close condition, not a hard level. Exit came at 7.135, below the 7.171 partial, because he closed the rest after a small pullback. | AF25: #107, #109, #113, #120 | AG25: https://discord.com/channels/1042855255089623100/1501271173588193290/1504388009280278589
A26: 25 | B26: 2026-05-14 20:27:12 | C26: BTCUSDT | D26: long | E26: loss | F26: stop_loss | J26: 81300 | K26: 81.3k CMP (msg 123), half margin by his own instruction | L26: 80800 | M26: 79500 | N26: 83000, 84000 | O26: HALF MARGIN, self-declared gamble - 'Don't lose today's profits on it, go low!' | P26: 81300 | V26: 2026-05-14 20:27:12 | W26: 2026-05-16 04:15:48 | X26: 31.8 | Y26: A self-described gamble long at 81.3k straight after the pump to 82k, targeting the daily high around 83k, or 84k if he saw strength. | Z26: He called it at 81.3k CMP with a DCA at 80.8k and 79.5k written as 'Sleep' (his wording for the stop), targeting the daily high at 83k or 84k, and stressed it was a half-margin gamble that should not cost anyone the day's profits (msgs 122-123). Price ran to 82k almost immediately - a clean scalp exit he chose not to take because he was holding out for 83k. He confirmed he was still holding the next morning (msg 127), then BTC rolled over and stopped him: 'Lost the BTC gamble trade. My fault there when we longed from 81.3k it immediately went to 82k, a good TP for scalp I could have exit there but was trying for 83k. My mistake on this one. The good part was I mentioned use less margin on this' (msg 128). | AA26: daily high | AB26: Immediately after the clarity-act pump to 82k that he had called from 79k (msg 121); he expected a slow grind and then a Sunday weekend pump (msg 126). | AD26: high | AE26: No card or exit price was posted; 79.5k is the published stop. Whether the 80.8k DCA filled is never stated - price traded through it on the way down, so the realised loss may be bigger than the call implies. avg_entry 81,300 is his own restatement of the entry in msg 128, not an exchange figure. | AF26: #122, #123, #127, #128 | AG26: https://discord.com/channels/1042855255089623100/1501271173588193290/1504535567663235103
A27: 26 | B27: 2026-05-15 02:59:36 | C27: HBARUSDT | D27: long | E27: loss | F27: stop_loss | J27: 0.0948 | K27: CMP | M27: 0.089 | N27: 0.1, 0.105 | V27: 2026-05-15 02:59:36 | W27: 2026-05-18 03:50:21 | X27: 72.8 | Y27: Straight long on HBAR at market with a 0.1-0.105 target zone; no reasoning beyond the levels was posted. | Z27: He called the long at 0.0948 CMP with a 0.089 stop and targets at 0.1-0.105, and confirmed twenty minutes later that HBAR and BTC were what he was still holding. It went nowhere for a day and a half; on 16 May he said HBAR was grinding back toward his entry and that he would look to close it around breakeven. That never happened - on 18 May he reported 'HBAR hit SL', so it closed at a full loss instead of the breakeven he wanted. | AD27: medium | AE27: He never restated a fill or an exit price, so avg_entry and exit_price are null; his published entry was 0.0948 and his published stop 0.089. The side on the stop-out message is inferred from the original call (the extractor flagged msg 144 as medium confidence). No R figure was given for the loss. | AF27: #125, #127, #139, #144 | AG27: https://discord.com/channels/1042855255089623100/1501271173588193290/1504634318503546950
A28: 27 | B28: 2026-05-16 04:23:08 | C28: PARTIUSDT | D28: long | E28: unknown | F28: unknown | J28: 0.0615 | K28: 0.0615 CMP with a 30% DCA leg below | L28: 0.586 | M28: 0.0525 | N28: 0.07, 0.075 | O28: DCA leg is 30% of the position | P28: 0.606 | Q28: None (fill implied by the average moving to 0.606 (as posted; reads as 0.0606) with the position in profit - he never posted a fill price) | V28: 2026-05-16 04:23:08 | Y28: A PARTI long at market with a 30% DCA leg underneath and targets in the 0.07-0.075 band. No reasoning was published beyond the levels. | Z28: He called it at 0.0615 CMP on the morning of 16 May with a 30% DCA leg (posted as 0.5860, which reads as 0.0586), targets 0.07-0.075 and a 0.0525 stop. Fifteen hours later he reported the average had moved to 0.606 - again a dropped decimal, reading as 0.0606 - and that the position was in profit, which implies the DCA leg filled. PARTI is never mentioned again: no exit, no stop, no result. | AC28: yes | AD28: medium | AE28: Two of his numbers are missing a decimal place - the DCA posted as 0.5860 and the average posted as 0.606 against a 0.0615 entry - and both are recorded exactly as posted rather than corrected. The DCA fill is inferred from the changed average. The position drops out of the log after 16 May with no outcome of any kind. | AF28: #129, #139 | AG28: https://discord.com/channels/1042855255089623100/1501271173588193290/1505017728887689278
A29: 28 | B29: 2026-05-16 04:26:35 | C29: LINKUSDT | D29: long | E29: not_taken | F29: not_taken | K29: CMP, and only if strength appeared in the market | M29: 9.6 | Y29: LINK looked good for a long, but there was no strength in the broader market, so the idea was conditional on strength showing up. | Z29: This was guidance rather than a trade he took: LINK looked good for a long but the market had no strength, so he told the group that if they saw some strength coming they could long it from CMP with a 9.6 stop. He never posted an entry of his own and never followed up, so nothing was managed or closed. | AB29: no strength in the market | AD29: medium | AE29: Conditional follower guidance with a stop but no entry price or target. There is no evidence he took it himself, hence not_taken. The later LINK mentions (msgs 995, 999) are about his spot bag and are tracked as a separate position. | AF29: #130 | AG29: https://discord.com/channels/1042855255089623100/1501271173588193290/1505018596701638706
A30: 29 | B30: 2026-05-16 12:58:40 | C30: ETHUSDT | D30: long | E30: breakeven | F30: breakeven | I30: 100 | J30: 2170 | K30: floated as a 5m-timeframe idea at 2170 CMP, then actually entered at 2172 CMP with 0.5% margin/risk | M30: 2145 | O30: Just an idea, won't count TP or SL, not an official trade; entered with 0.5% margin/risk only - SCALP and SMALL margin | P30: 2173.61 | T30: 25% at 2194.45 | V30: 2026-05-16 13:35:54 | W30: 2026-05-18 03:50:15 | X30: 38.2 | Y30: A low-timeframe (5m) ETH long for people who like LTF entries, deliberately not counted as an official call and taken with tiny margin. | Z30: He floated the 5m long at 2170 with a 2145 stop as 'just an idea, not an official trade', then 37 minutes later actually entered at 2172 using only 0.5% margin, stressing it was a scalp on small size. That evening the bounce looked weak and he offered anyone in small profit the chance to exit, saying he was taking his chance; the next day it was still crawling ('shits always the slowest'). On 17 May it went past 1R at 2194.45 (+90.57% at 100x) and he told followers they could take 25-50% off there, and later that the entry was still valid with the same 2145 stop. It then round-tripped and closed flat - 'ETH hit BE' - on 18 May. | AA30: 5m timeframe | AB30: weak bounce, he expected lower prices | AD30: medium | AE30: The 25% partial at 1R is phrased as advice to followers ('you can take 25-50% here'), so whether he trimmed himself is unclear; if he did, the net result is a small win rather than flat. He posted no breakeven price. Recorded as breakeven because that is how he reported the close. | AF30: #135, #136, #137, #138, #139, #140, #142, #143 | AG30: https://discord.com/channels/1042855255089623100/1501271173588193290/1505147469187645451
A31: 30 | B31: 2026-05-16 12:58:40 | C31: BTCUSDT | D31: long | E31: unknown | F31: unknown | J31: 78000 | K31: CMP at the time (78k), a 5m-timeframe entry for people who like LTF entries | M31: 77700 | O31: Explicitly not an official trade - 'Just an idea won't count TP or SL' | Y31: A 5m-timeframe scalp long inside the 77.7-78.1k weekend reversal zone he had flagged that morning. | Z31: In the morning he said the weekend reversal zone should be 77.7-78.1k and that he would try a scalp there, re-posting the plan as a screenshot (msgs 133-134). At 12:58 he gave the entry for LTF traders - long at CMP 78k with a 77.7k stop - but framed it explicitly as an idea that would not count as an official trade with a TP or SL (msg 135). No fill, result or close was ever posted for it, and the next BTC idea came six hours later with a different (76.9k) stop. | AA31: 5m timeframe, 4h close | AB31: Weekend. He expected 77.7-78.1k to be the reversal zone, a bounce there to target 79-80k, and a 4h close below 77.7k to open 75-76k (msgs 133-134). | AD31: low | AE31: Kept as a position because it was published as a call with an entry and a stop, but he said it would not count and no fill or exit was ever posted, so outcome is not_taken. It may in fact be the trade behind the 78,041.30 / 150x card in msg 141, which is attached here to the later msg 139 idea. Separately that morning he published a conditional plan to limit-long 76,850 with TP 80-82k and SL 75k if BTC lost the level (msgs 131-132); BTC bottomed around 77.7k so that limit never came into play and it is not recorded as a position. [AUDIT] Audit: he never refused this trade — "won't count TP or SL, not an official trade" is a stats disclaimer, and MSG 141 shows his own 150x card from 78,041.3 at this level. Outcome changed from not_taken to unknown. | AF31: #133, #134, #135 | AG31: https://discord.com/channels/1042855255089623100/1501271173588193290/1505102808389783632
A32: 31 | B32: 2026-05-16 19:29:46 | C32: BTCUSDT | D32: long | E32: unknown | F32: unknown | I32: 150 | K32: CMP at 05-16 19:29 - no price given in the call; the card he posted the next day shows an entry of 78,041.30 | M32: 76900 | O32: Offered as an optional idea - 'if anyone wants to try BTC long' | P32: 78041.3 | V32: 2026-05-16 19:29:46 | Y32: He thought BTC had bottomed for the weekend, so he offered a long from market with a stop under 76.9k. | Z32: He posted it as an optional idea: 'If anyone wants to try BTC long you can from CMP with SL 76.9k think we bottomed for weekend' (msg 139). The next afternoon he showed it running in profit - 150x card, entry 78,041.30 against 78,494.90, +87.18% - with 'BTC moving too if anyone took that idea' (msg 141), and said the entry was still valid from there with the same stop even though price was up from it (msg 142). The following evening he added that probably nobody took it although it was near the bottom and valid, and used it to explain that he often runs two BTC setups at once: scalps he does very often (high win rate, low RR) and swings (low win rate, high RR) (msg 149). No exit, close or result was ever posted for this one. | AB32: Weekend bottom-fishing after the gamble long was stopped; BTC was holding the 4h support / 200 EMA region around 77.7k. | AD32: low | AE32: Outcome unknown - he never closed it publicly and never referred to it again after msg 149, while separately running the 05-18 long. The 78,041.30 / 150x card is linked here because msg 142 repeats the 76.9k stop of this idea, but it could equally belong to the msg 135 LTF idea at 78k. still_open_at_end is false because nothing in the log tracks it any further, not because a close was stated. | AF32: #139, #141, #142, #149 | AG32: https://discord.com/channels/1042855255089623100/1501271173588193290/1505245889567002787
A33: 32 | B33: 2026-05-18 03:50:36 | C33: BTCUSDT | D33: long | E33: win | F33: manual_close | G33: 1 | H33: 219.32 | I33: 150 | J33: 77000 | K33: 77k CMP; 50% of size held back for the 76.4k DCA | L33: 76400 | M33: 75400 | P33: 76704.7 | Q33: 76400 (50% DCA filled, average entry 76.7k and in profit) | S33: 77800 -> 78500 | U33: 77826.3 | V33: 2026-05-18 03:50:36 | W33: 2026-05-21 04:30:48 | X33: 72.7 | Y33: Swing long from 77k with a 76.4k DCA, playing the weekend bottom and the reclaim of the 200 EMA on lower timeframes for a move to 78k+. | Z33: He called it at 77k CMP with a 75.4k stop and no target (msg 145), adding a 50% DCA at 76.4k a minute later (msg 146). Being busy that day, he left contingency instructions for followers - take 20-25% around 77.8k and move the stop to entry if he did not update (msg 147) - but kept managing it himself and reported no changes that evening (msg 148). The DCA filled at 76.4k, taking his average to 76.7k in profit (msg 152). He held through the weekend showing the 150x card at 76,704.70 (msg 160) and pointed to the 200 EMA reclaim as confirmation (msg 162). At around 1R he told members to take partials whenever they liked while stating he personally avoids partials, especially on BTC, and that he was holding for about 78.5k (msg 167). He closed the whole position the next morning at 77,826.30 for +219.32% on 150x: 'BTC closed here, over 1R + with a DCA great profits for me' (msg 170). | AA33: EMA 200 | AB33: After the weekend flush; BTC reclaimed the 200 EMA on lower timeframes after about two days, which he read as bullish for the position. | AD33: high | AE33: r_multiple is his own words - 'over 1R' - recorded as 1.0, which understates it slightly; it is not computed from prices. The 77.8k trim and the stop-to-entry move (msg 147) were contingency guidance for followers - he took no partials and never posted a stop move himself. Around this trade (msg 149) he explained he sometimes runs a scalp and a swing BTC setup at the same time, which is why an earlier 05-16 idea may still have been open alongside it. | AF33: #145, #146, #147, #148, #152, #160, #162, #167, #170 | AG33: https://discord.com/channels/1042855255089623100/1501271173588193290/1505734318432059444
A34: 33 | B34: 2026-05-18 17:05:56 | C34: BOMEUSDT | D34: long | E34: win | F34: take_profit | H34: 165.91 | I34: 25 | J34: 0.000599 | K34: 0.000599 CMP, framed as a scalp on a shitcoin | M34: 0.00053 | N34: 0.00064, 0.000669 | O34: manage your risk; small accounts should close entirely at the first partial | P34: 0.0005998 | R34: 0.0005998 (to_entry) | T34: 25% at 0.0006203 | V34: 2026-05-18 17:05:56 | W34: 2026-05-19 10:30:37 | X34: 17.4 | Y34: A scalp on a shitcoin - long BOME at 0.000599 towards 0.00064-0.000669, with the stop set as a 4h close under 0.00055 or a hard 0.00053. | Z34: He opened the scalp at 0.000599 CMP with targets at 0.00064-0.000669 and a hard stop at 0.00053. Twenty minutes in he pointed out BOME was holding its level despite the BTC dump but warned it could still turn. Overnight he banked 25% at 0.0006203 (+80.8% at 25x) and moved the stop to entry, telling small accounts to just close the whole thing there or exit at the first target. By late morning BOME had exploded through the first target and he took profit at 0.000643 for +165.91%. | AA34: 4h close | AB34: BTC dumping while BOME held up | AD34: medium | AE34: He does not say whether the 'TP' at 0.000643 closed the rest of the position or was another partial, so the exit is recorded at that level. On 3 Aug (MSG 866) he mentions seeing a BOME short opportunity but explicitly does not take it - no position from that. [AUDIT] Audit: 0.000643 is the mark price on an open-position ROI card, not a close — exit_price cleared to null. The 25% partial comes from "Take 25%" (follower instruction), so it may not be his own action. | AF34: #150, #151, #154, #156 | AG34: https://discord.com/channels/1042855255089623100/1501271173588193290/1505934468681306273
A35: 34 | B35: 2026-05-18 22:14:08 | C35: ZECUSDT | D35: long | E35: win | F35: take_profit | G35: 1 | H35: 493.44 | I35: 75 | J35: 544 | K35: 544 CMP | M35: 505 | N35: 580, 600 | P35: 545.99 | Q35: 582 ('saw strength and added alot at 582' - the added leg's own card shows entry 580.25. The add happened before this message, which is where he explains the changed average) | R35: 545.99 (to_entry) | S35: 592 | T35: 20% at 572.12 | 581.92 | U35: 592 | V35: 2026-05-18 22:14:08 | W35: 2026-05-20 09:20:47 | X35: 35.1 | Y35: Long ZEC at 544 for a push into the 580-600 band - and when it got there he added heavily on strength rather than getting out, then took the whole thing off at 592. | Z35: He called it at 544 CMP with a 505 stop and 580-600 targets. Six hours in, with the 75x card at +358.87%, he took 20% at 572.12 and moved the stop to his 545.99 entry, saving the majority for the targets. At 21:04 the first target hit at 581.92 for what he called about 1R and he booked the majority there, naming 592 as the full exit. He then added a lot at 582 on strength, changing his average - a second card shows that leg entered at 580.25. On the morning of 20 May the 592 exit filled and he was fully out, saying he believed it would go higher but was happy to leave. The added leg's card confirms it closed at 591.75 for +148.59%. | AB35: shit market | AD35: high | AE35: Two entry figures coexist: the card's 545.99 and his own 'the original entry was from 540'. The 1R is his description of the 581.92 take-profit, not a final tally for the trade. Msg 166 is a verbatim repost of msg 163, so the 582 add is counted once. | AF35: #153, #155, #158, #163, #164, #165, #166 | AG35: https://discord.com/channels/1042855255089623100/1501271173588193290/1506012029968977950
A36: 35 | B36: 2026-05-19 10:48:14 | C36: SUIUSDT | D36: long | E36: win | F36: take_profit | H36: 308.25 | I36: 50 | J36: 1.09 | K36: 1.09 CMP, deliberately taken small so there was room to add | M36: 1.01 | O36: Personally took a small position, scalp; the DCA was optional and only for anyone not already sized up | P36: 1.0738 | Q36: None (a small 25% DCA - he only gave the resulting average, 1.076. The separate DCA card in msg 173 shows a 100x leg entered at 1.0481) | R36: 1.0 (widened) | S36: 1.14/1.23 | U36: 1.14 | V36: 2026-05-19 10:48:14 | W36: 2026-05-21 05:57:24 | X36: 43.2 | Y36: A small scalp long on SUI at 1.09, sized down on purpose so he had room to add into weakness rather than defend a big position. | Z36: He called it as a small scalp at 1.09 CMP with a 1.01 stop and no target. Overnight he widened the stop to 1.00, saying the position was small enough to absorb it, and on the morning of 20 May added a small 25% DCA that brought his average to 1.076 - optional, and only for anyone not already in heavy. On 21 May he finally gave targets: 1.14 for himself, 1.23 for anyone holding longer, with the 50x card at +170.83%. The 1.14 filled less than an hour after he posted it and he called it a good start to the day. A second card shows the DCA leg, a 100x from 1.0481, closing at 1.1401 for +877.77%. | AD36: high | AE36: He ran this on two cards at once - a 50x leg (entry 1.0738) and a 100x DCA leg (entry 1.0481) - which is one position, not two. His stated average after the DCA (1.076) matches neither card exactly, and the DCA fill price was never posted. | AF36: #157, #159, #161, #171, #172, #173 | AG36: https://discord.com/channels/1042855255089623100/1501271173588193290/1506201807385264220
